Workbook
Name \0: #REF!
Name \0: #REF!
Name \0: #REF!
Name \0: #REF!
Name \5: #REF!
Name \5: #REF!
Name \7: #REF!
Name \7: #REF!
Name \8: #REF!
Name \A: #REF!
Name \a: #N/A
Name \A: #REF!
Name \A: #REF!
Name \B: #REF!
Name \b: #REF!
Name \B: #REF!
Name \B: #REF!
Name \c: #REF!
Name \c: #REF!
Name \D: #REF!
Name \d: #REF!
Name \E: #REF!
Name \E: #REF!
Name \E: #REF!
Name \f: #REF!
Name \G: #REF!
Name \G: #REF!
Name \G: #REF!
Name \H: #REF!
Name \H: #REF!
Name \H: #REF!
Name \I: #REF!
Name \I: #REF!
Name \I: #REF!
Name \J: #REF!
Name \J: #REF!
Name \J: #REF!
Name \K: #REF!
Name \K: #REF!
Name \K: #REF!
Name \L: #REF!
Name \L: #REF!
Name \L: #REF!
Name \m: #REF!
Name \m: #REF!
Name \m: #REF!
Name \n: #REF!
Name \n: #REF!
Name \n: #REF!
Name \O: #REF!
Name \O: #REF!
Name \O: #REF!
Name \P: #REF!
Name \P: #REF!
Name \P: #REF!
Name \P24: #REF!
Name \P24: #REF!
Name \P24: #REF!
Name \PP: #REF!
Name \PP: #REF!

Sheet Cover
C13: Project BORACAY
C14: Bonchon Financial Model
C15: January 2026

Sheet Table of Contents
C2: Project BORACAY
C3: Bonchon Financial Model
C5: Table of Contents
C6: Assumptions
C8: Annual P&Ls
C9: Consolidated P&L
C10: Bonchon U.S. P&L
C11: Bonchon International P&L
C12: Consolidations P&L
C14: 2025 Monthly P&Ls
C15: Consolidated P&L (Monthly)
C16: Bonchon U.S. P&L (Monthly)
... C41: Embedded Growth

Sheet Summary>>

Sheet Assumptions
B3: Basis of Financial Presentation
B16: 2025A-2030P Growth Assumptions
B46: Sauce Economics Overview
B83: SG&A Detail
B130: Capex Detail
B142: FX Treatment and Assumptions

Sheet Annual P&Ls>>

Sheet Consolidated P&L
B2: Bonchon Consolidated P&L
C4: Historical | H4: Projected | N4: CAGR
B5: ($ in millions) | C5: 2021 | D5: 2022 | E5: 2023 | F5: 2024 | G5: 2025A | H5: 2026E | I5: 2027P | J5: 2028P | K5: 2029P | L5: 2030P | N5: '21A-'25E | O5: '25E-'30P
B7: U.S. Restaurants | C7: ='Bonchon U.S. P&L'!C9 -> 115 | D7: ='Bonchon U.S. P&L'!D9 -> 122 | E7: ='Bonchon U.S. P&L'!E9 -> 131 | F7: ='Bonchon U.S. P&L'!F9 -> 147 | G7: ='Bonchon U.S. P&L'!G9 -> 151 | H7: ='Bonchon U.S. P&L'!H9 -> 179 | I7: ='Bonchon U.S. P&L'!I9 -> 209 | J7: ='Bonchon U.S. P&L'!J9 -> 244 | ... L7: ='Bonchon U.S. P&L'!L9 -> 344 | N7: =IFERROR(_xlfn.RRI(4,C7,G7),"-") -> 0.070458356 | O7: =IFERROR(_xlfn.RRI(5,G7,L7),"-") -> 0.17900677
B8: International Restaurants | C8: ='Bonchon International P&L'!C20 -> 274 | D8: ='Bonchon International P&L'!D20 -> 287 | E8: ='Bonchon International P&L'!E20 -> 304 | F8: ='Bonchon International P&L'!F20 -> 324 | G8: ='Bonchon International P&L'!G20 -> 347 | H8: ='Bonchon International P&L'!H20 -> 376 | I8: ='Bonchon International P&L'!I20 -> 414 | J8: ='Bonchon International P&L'!J20 -> 459 | ... L8: ='Bonchon International P&L'!L20 -> 561 | N8: =IFERROR(_xlfn.RRI(4,C8,G8),"-") -> 0.060827399 | O8: =IFERROR(_xlfn.RRI(5,G8,L8),"-") -> 0.10084628
B9: Systemwide Restaurants | C9: =SUM(C7:C8) -> 389 | D9: =SUM(D7:D8) -> 409 | E9: =SUM(E7:E8) -> 435 | F9: =SUM(F7:F8) -> 471 | G9: =SUM(G7:G8) -> 498 | H9: =SUM(H7:H8) -> 555 | I9: =SUM(I7:I8) -> 623 | J9: =SUM(J7:J8) -> 703 | ... L9: =SUM(L7:L8) -> 905 | N9: =IFERROR(_xlfn.RRI(4,C9,G9),"-") -> 0.063701901 | O9: =IFERROR(_xlfn.RRI(5,G9,L9),"-") -> 0.12689603
B10: % Growth | D10: =IFERROR(D9/C9-1,0) -> 0.051413882 | E10: =IFERROR(E9/D9-1,0) -> 0.063569682 | F10: =IFERROR(F9/E9-1,0) -> 0.082758621 | G10: =IFERROR(G9/F9-1,0) -> 0.057324841 | H10: =IFERROR(H9/G9-1,0) -> 0.11445783 | I10: =IFERROR(I9/H9-1,0) -> 0.12252252 | J10: =IFERROR(J9/I9-1,0) -> 0.12841091 | K10: =IFERROR(K9/J9-1,0) -> 0.13513514 | L10: =IFERROR(L9/K9-1,0) -> 0.13408521
B12: U.S. | C12: ='Bonchon U.S. P&L'!C12 -> 173.415 | D12: ='Bonchon U.S. P&L'!D12 -> 193.64356 | E12: ='Bonchon U.S. P&L'!E12 -> 200.67402 | F12: ='Bonchon U.S. P&L'!F12 -> 202.35598 | G12: ='Bonchon U.S. P&L'!G12 -> 211.07983 | H12: ='Bonchon U.S. P&L'!H12 -> 236.36305 | I12: ='Bonchon U.S. P&L'!I12 -> 290.17861 | J12: ='Bonchon U.S. P&L'!J12 -> 352.66562 | ... L12: ='Bonchon U.S. P&L'!L12 -> 533.59659 | N12: =IFERROR(_xlfn.RRI(4,C12,G12),"-") -> 0.050364462 | O12: =IFERROR(_xlfn.RRI(5,G12,L12),"-") -> 0.20379702
B13: International | C13: ='Bonchon International P&L'!C23 -> 103.10846 | D13: ='Bonchon International P&L'!D23 -> 133.7085 | E13: ='Bonchon International P&L'!E23 -> 144.83545 | F13: ='Bonchon International P&L'!F23 -> 154.48318 | G13: ='Bonchon International P&L'!G23 -> 170.03361 | H13: ='Bonchon International P&L'!H23 -> 181.55199 | I13: ='Bonchon International P&L'!I23 -> 207.69386 | J13: ='Bonchon International P&L'!J23 -> 239.16518 | ... L13: ='Bonchon International P&L'!L23 -> 319.15817 | N13: =IFERROR(_xlfn.RRI(4,C13,G13),"-") -> 0.13320926 | O13: =IFERROR(_xlfn.RRI(5,G13,L13),"-") -> 0.13421201
B14: Systemwide Sales | C14: =SUM(C12:C13) -> 276.52346 | D14: =SUM(D12:D13) -> 327.35207 | E14: =SUM(E12:E13) -> 345.50947 | F14: =SUM(F12:F13) -> 356.83916 | G14: =SUM(G12:G13) -> 381.11344 | H14: =SUM(H12:H13) -> 417.91503 | I14: =SUM(I12:I13) -> 497.87246 | J14: =SUM(J12:J13) -> 591.8308 | ... L14: =SUM(L12:L13) -> 852.75476 | N14: =IFERROR(_xlfn.RRI(4,C14,G14),"-") -> 0.083504126 | O14: =IFERROR(_xlfn.RRI(5,G14,L14),"-") -> 0.17477306
B15: % Growth | D15: =IFERROR(D14/C14-1,0) -> 0.183813 | E15: =IFERROR(E14/D14-1,0) -> 0.055467502 | F15: =IFERROR(F14/E14-1,0) -> 0.032791251 | G15: =IFERROR(G14/F14-1,0) -> 0.068025831 | H15: =IFERROR(H14/G14-1,0) -> 0.096563363 | I15: =IFERROR(I14/H14-1,0) -> 0.19132461 | J15: =IFERROR(J14/I14-1,0) -> 0.1887197 | K15: =IFERROR(K14/J14-1,0) -> 0.19692414 | L15: =IFERROR(L14/K14-1,0) -> 0.20381559
B17: U.S. Same Store Sales | C17: ='Bonchon U.S. P&L'!C15 -> 0.16753805 | D17: ='Bonchon U.S. P&L'!D15 -> 0.049974743 | E17: ='Bonchon U.S. P&L'!E15 -> -0.033246735 | F17: ='Bonchon U.S. P&L'!F15 -> -0.079297458 | G17: ='Bonchon U.S. P&L'!G15 -> 8.3373689e-05 | H17: ='Bonchon U.S. P&L'!H15 -> 0.05043868 | I17: ='Bonchon U.S. P&L'!I15 -> 0.04 | J17: ='Bonchon U.S. P&L'!J15 -> 0.04 | ... L17: ='Bonchon U.S. P&L'!L15 -> 0.04
B18: International Same Store Sales | C18: ='Bonchon International P&L'!C29 -> -0.16075935 | D18: ='Bonchon International P&L'!D29 -> 0.15699898 | E18: ='Bonchon International P&L'!E29 -> 0.019225146 | F18: ='Bonchon International P&L'!F29 -> 0.010998005 | G18: ='Bonchon International P&L'!G29 -> 0.055085803 | H18: ='Bonchon International P&L'!H29 -> 0.05 | I18: ='Bonchon International P&L'!I29 -> 0.05 | J18: ='Bonchon International P&L'!J29 -> 0.05 | ... L18: ='Bonchon International P&L'!L29 -> 0.05
B19: Systemwide Same Store Sales | C19: 0.020999098 | D19: 0.092648212 | E19: -0.010871634 | F19: -0.039606542 | G19: 0.024720986 | H19: =(H17*(H12/H14))+(H18*(H13/H14)) -> 0.050248107 | I19: =(I17*(I12/I14))+(I18*(I13/I14)) -> 0.044171628 | J19: =(J17*(J12/J14))+(J18*(J13/J14)) -> 0.044041107 | K19: =(K17*(K12/K14))+(K18*(K13/K14)) -> 0.043903941 | L19: =(L17*(L12/L14))+(L18*(L13/L14)) -> 0.043742672
B21: Franchise Revenue | C21: ='Bonchon U.S. P&L'!C17+'Bonchon International P&L'!C31-'Consolidations P&L'!C7 -> 11.362014 | D21: ='Bonchon U.S. P&L'!D17+'Bonchon International P&L'!D31-'Consolidations P&L'!D7 -> 13.069418 | E21: ='Bonchon U.S. P&L'!E17+'Bonchon International P&L'!E31-'Consolidations P&L'!E7 -> 13.946716 | F21: ='Bonchon U.S. P&L'!F17+'Bonchon International P&L'!F31-'Consolidations P&L'!F7 -> 14.441046 | G21: ='Bonchon U.S. P&L'!G17+'Bonchon International P&L'!G31-'Consolidations P&L'!G7 -> 15.092833 | H21: ='Bonchon U.S. P&L'!H17+'Bonchon International P&L'!H31-'Consolidations P&L'!H7 -> 16.733238 | I21: ='Bonchon U.S. P&L'!I17+'Bonchon International P&L'!I31-'Consolidations P&L'!I7 -> 19.88653 | J21: ='Bonchon U.S. P&L'!J17+'Bonchon International P&L'!J31-'Consolidations P&L'!J7 -> 25.43262 | ... L21: ='Bonchon U.S. P&L'!L17+'Bonchon International P&L'!L31-'Consolidations P&L'!L7 -> 37.79932 | N21: =IFERROR(_xlfn.RRI(4,C21,G21),"-") -> 0.073566279 | O21: =IFERROR(_xlfn.RRI(5,G21,L21),"-") -> 0.2015522
B22: Sauce Revenue | C22: ='Bonchon U.S. P&L'!C18+'Bonchon International P&L'!C32-'Consolidations P&L'!C8 -> 5.7911749 | D22: ='Bonchon U.S. P&L'!D18+'Bonchon International P&L'!D32-'Consolidations P&L'!D8 -> 7.1760565 | E22: ='Bonchon U.S. P&L'!E18+'Bonchon International P&L'!E32-'Consolidations P&L'!E8 -> 7.8954667 | F22: ='Bonchon U.S. P&L'!F18+'Bonchon International P&L'!F32-'Consolidations P&L'!F8 -> 8.2833766 | G22: ='Bonchon U.S. P&L'!G18+'Bonchon International P&L'!G32-'Consolidations P&L'!G8 -> 7.3720481 | H22: ='Bonchon U.S. P&L'!H18+'Bonchon International P&L'!H32-'Consolidations P&L'!H8 -> 8.0986798 | I22: ='Bonchon U.S. P&L'!I18+'Bonchon International P&L'!I32-'Consolidations P&L'!I8 -> 9.3248687 | J22: ='Bonchon U.S. P&L'!J18+'Bonchon International P&L'!J32-'Consolidations P&L'!J8 -> 11.033129 | ... L22: ='Bonchon U.S. P&L'!L18+'Bonchon International P&L'!L32-'Consolidations P&L'!L8 -> 17.244961 | N22: =IFERROR(_xlfn.RRI(4,C22,G22),"-") -> 0.062197733 | O22: =IFERROR(_xlfn.RRI(5,G22,L22),"-") -> 0.18526323
B23: Company-Owned Store Revenue | C23: ='Bonchon U.S. P&L'!C19+'Bonchon International P&L'!C33-'Consolidations P&L'!C9 -> 1.7976949 | D23: ='Bonchon U.S. P&L'!D19+'Bonchon International P&L'!D33-'Consolidations P&L'!D9 -> 5.1372586 | E23: ='Bonchon U.S. P&L'!E19+'Bonchon International P&L'!E33-'Consolidations P&L'!E9 -> 5.0760827 | F23: ='Bonchon U.S. P&L'!F19+'Bonchon International P&L'!F33-'Consolidations P&L'!F9 -> 4.1612575 | G23: ='Bonchon U.S. P&L'!G19+'Bonchon International P&L'!G33-'Consolidations P&L'!G9 -> 3.7884491 | H23: ='Bonchon U.S. P&L'!H19+'Bonchon International P&L'!H33-'Consolidations P&L'!H9 -> 4.3374481 | I23: ='Bonchon U.S. P&L'!I19+'Bonchon International P&L'!I33-'Consolidations P&L'!I9 -> 6.2884611 | J23: ='Bonchon U.S. P&L'!J19+'Bonchon International P&L'!J33-'Consolidations P&L'!J9 -> 6.9173072 | ... L23: ='Bonchon U.S. P&L'!L19+'Bonchon International P&L'!L33-'Consolidations P&L'!L9 -> 8.3699417 | N23: =IFERROR(_xlfn.RRI(4,C23,G23),"-") -> 0.20485939 | O23: =IFERROR(_xlfn.RRI(5,G23,L23),"-") -> 0.17179649
B24: Marketing Fund | C24: ='Bonchon U.S. P&L'!C20+'Bonchon International P&L'!C34-'Consolidations P&L'!C10 -> 1.7094527 | D24: ='Bonchon U.S. P&L'!D20+'Bonchon International P&L'!D34-'Consolidations P&L'!D10 -> 2.1685849 | E24: ='Bonchon U.S. P&L'!E20+'Bonchon International P&L'!E34-'Consolidations P&L'!E10 -> 2.8156541 | F24: ='Bonchon U.S. P&L'!F20+'Bonchon International P&L'!F34-'Consolidations P&L'!F10 -> 3.2534763 | G24: ='Bonchon U.S. P&L'!G20+'Bonchon International P&L'!G34-'Consolidations P&L'!G10 -> 3.2282713 | H24: ='Bonchon U.S. P&L'!H20+'Bonchon International P&L'!H34-'Consolidations P&L'!H10 -> 4.9917485 | I24: ='Bonchon U.S. P&L'!I20+'Bonchon International P&L'!I34-'Consolidations P&L'!I10 -> 8.5167043 | J24: ='Bonchon U.S. P&L'!J20+'Bonchon International P&L'!J34-'Consolidations P&L'!J10 -> 13.829933 | ... L24: ='Bonchon U.S. P&L'!L20+'Bonchon International P&L'!L34-'Consolidations P&L'!L10 -> 21.009066 | N24: =IFERROR(_xlfn.RRI(4,C24,G24),"-") -> 0.17227159 | O24: =IFERROR(_xlfn.RRI(5,G24,L24),"-") -> 0.45441164
B25: Other Product Revenue | C25: ='Bonchon U.S. P&L'!C21+'Bonchon International P&L'!C35-'Consolidations P&L'!C11 -> -0.035375888 | D25: ='Bonchon U.S. P&L'!D21+'Bonchon International P&L'!D35-'Consolidations P&L'!D11 -> -0.070617026 | E25: ='Bonchon U.S. P&L'!E21+'Bonchon International P&L'!E35-'Consolidations P&L'!E11 -> 0.37069759 | F25: ='Bonchon U.S. P&L'!F21+'Bonchon International P&L'!F35-'Consolidations P&L'!F11 -> 0.15019239 | G25: ='Bonchon U.S. P&L'!G21+'Bonchon International P&L'!G35-'Consolidations P&L'!G11 -> 0.0063102521 | H25: ='Bonchon U.S. P&L'!H21+'Bonchon International P&L'!H35-'Consolidations P&L'!H11 -> 0.026584105 | I25: ='Bonchon U.S. P&L'!I21+'Bonchon International P&L'!I35-'Consolidations P&L'!I11 -> 0.040422701 | J25: ='Bonchon U.S. P&L'!J21+'Bonchon International P&L'!J35-'Consolidations P&L'!J11 -> 0.047549874 | ... L25: ='Bonchon U.S. P&L'!L21+'Bonchon International P&L'!L35-'Consolidations P&L'!L11 -> 0.064551041 | N25: =IFERROR(_xlfn.RRI(4,C25,G25),"-") -> - | O25: =IFERROR(_xlfn.RRI(5,G25,L25),"-") -> 0.59210354
B26: Other Revenue | C26: ='Bonchon U.S. P&L'!C22+'Bonchon International P&L'!C36-'Consolidations P&L'!C12 -> 0.30773293 | D26: ='Bonchon U.S. P&L'!D22+'Bonchon International P&L'!D36-'Consolidations P&L'!D12 -> 0.12628718 | E26: ='Bonchon U.S. P&L'!E22+'Bonchon International P&L'!E36-'Consolidations P&L'!E12 -> 0.27595889 | F26: ='Bonchon U.S. P&L'!F22+'Bonchon International P&L'!F36-'Consolidations P&L'!F12 -> 0.1570314 | G26: ='Bonchon U.S. P&L'!G22+'Bonchon International P&L'!G36-'Consolidations P&L'!G12 -> 0.17322978 | H26: ='Bonchon U.S. P&L'!H22+'Bonchon International P&L'!H36-'Consolidations P&L'!H12 -> 0.20392759 | I26: ='Bonchon U.S. P&L'!I22+'Bonchon International P&L'!I36-'Consolidations P&L'!I12 -> 0.2275 | J26: ='Bonchon U.S. P&L'!J22+'Bonchon International P&L'!J36-'Consolidations P&L'!J12 -> 0.26 | ... L26: ='Bonchon U.S. P&L'!L22+'Bonchon International P&L'!L36-'Consolidations P&L'!L12 -> 0.39 | N26: =IFERROR(_xlfn.RRI(4,C26,G26),"-") -> -0.13381203 | O26: =IFERROR(_xlfn.RRI(5,G26,L26),"-") -> 0.1762196
B27: Other | C27: =SUM(C25:C26) -> 0.27235704 | D27: =SUM(D25:D26) -> 0.055670154 | E27: =SUM(E25:E26) -> 0.64665648 | F27: =SUM(F25:F26) -> 0.30722379 | G27: =SUM(G25:G26) -> 0.17954003 | H27: =SUM(H25:H26) -> 0.23051169 | I27: =SUM(I25:I26) -> 0.2679227 | J27: =SUM(J25:J26) -> 0.30754987 | ... L27: =SUM(L25:L26) -> 0.45455104 | N27: =IFERROR(_xlfn.RRI(4,C27,G27),"-") -> -0.098935928 | O27: =IFERROR(_xlfn.RRI(5,G27,L27),"-") -> 0.20416021
B28: Total Revenue | C28: =SUM(C21:C24,C27) -> 20.932693 | D28: =SUM(D21:D24,D27) -> 27.606988 | E28: =SUM(E21:E24,E27) -> 30.380576 | F28: =SUM(F21:F24,F27) -> 30.44638 | G28: =SUM(G21:G24,G27) -> 29.661142 | H28: =SUM(H21:H24,H27) -> 34.391626 | I28: =SUM(I21:I24,I27) -> 44.284486 | J28: =SUM(J21:J24,J27) -> 57.520539 | ... L28: =SUM(L21:L24,L27) -> 84.877839 | N28: =IFERROR(_xlfn.RRI(4,C28,G28),"-") -> 0.091040035 | O28: =IFERROR(_xlfn.RRI(5,G28,L28),"-") -> 0.23401742
B29: % Growth | D29: =IFERROR(D28/C28-1,0) -> 0.31884547 | E29: =IFERROR(E28/D28-1,0) -> 0.1004669 | F29: =IFERROR(F28/E28-1,0) -> 0.0021659763 | G29: =IFERROR(G28/F28-1,0) -> -0.025790865 | H29: =IFERROR(H28/G28-1,0) -> 0.15948424 | I29: =IFERROR(I28/H28-1,0) -> 0.28765317 | J29: =IFERROR(J28/I28-1,0) -> 0.29888688 | K29: =IFERROR(K28/J28-1,0) -> 0.22427322 | L29: =IFERROR(L28/K28-1,0) -> 0.20529408
B31: Sauce COGS | C31: ='Bonchon U.S. P&L'!C27+'Bonchon International P&L'!C41-'Consolidations P&L'!C17 -> 0.86757262 | D31: ='Bonchon U.S. P&L'!D27+'Bonchon International P&L'!D41-'Consolidations P&L'!D17 -> 1.2818111 | E31: ='Bonchon U.S. P&L'!E27+'Bonchon International P&L'!E41-'Consolidations P&L'!E17 -> 1.5984929 | F31: ='Bonchon U.S. P&L'!F27+'Bonchon International P&L'!F41-'Consolidations P&L'!F17 -> 1.4781993 | G31: ='Bonchon U.S. P&L'!G27+'Bonchon International P&L'!G41-'Consolidations P&L'!G17 -> 1.3179227 | H31: ='Bonchon U.S. P&L'!H27+'Bonchon International P&L'!H41-'Consolidations P&L'!H17 -> 1.3505507 | I31: ='Bonchon U.S. P&L'!I27+'Bonchon International P&L'!I41-'Consolidations P&L'!I17 -> 1.5339579 | J31: ='Bonchon U.S. P&L'!J27+'Bonchon International P&L'!J41-'Consolidations P&L'!J17 -> 1.7648955 | ... L31: ='Bonchon U.S. P&L'!L27+'Bonchon International P&L'!L41-'Consolidations P&L'!L17 -> 2.3941645 | N31: =IFERROR(_xlfn.RRI(4,C31,G31),"-") -> 0.1101867 | O31: =IFERROR(_xlfn.RRI(5,G31,L31),"-") -> 0.1268155
B32: Company-Owned Store COGS | C32: ='Bonchon U.S. P&L'!C28+'Bonchon International P&L'!C42-'Consolidations P&L'!C18 -> 0.57564599 | D32: ='Bonchon U.S. P&L'!D28+'Bonchon International P&L'!D42-'Consolidations P&L'!D18 -> 1.5265284 | E32: ='Bonchon U.S. P&L'!E28+'Bonchon International P&L'!E42-'Consolidations P&L'!E18 -> 1.4018693 | F32: ='Bonchon U.S. P&L'!F28+'Bonchon International P&L'!F42-'Consolidations P&L'!F18 -> 1.4141352 | G32: ='Bonchon U.S. P&L'!G28+'Bonchon International P&L'!G42-'Consolidations P&L'!G18 -> 1.0689561 | H32: ='Bonchon U.S. P&L'!H28+'Bonchon International P&L'!H42-'Consolidations P&L'!H18 -> 1.2437544 | I32: ='Bonchon U.S. P&L'!I28+'Bonchon International P&L'!I42-'Consolidations P&L'!I18 -> 1.7413943 | J32: ='Bonchon U.S. P&L'!J28+'Bonchon International P&L'!J42-'Consolidations P&L'!J18 -> 1.8960876 | ... L32: ='Bonchon U.S. P&L'!L28+'Bonchon International P&L'!L42-'Consolidations P&L'!L18 -> 2.2650287 | N32: =IFERROR(_xlfn.RRI(4,C32,G32),"-") -> 0.16735002 | O32: =IFERROR(_xlfn.RRI(5,G32,L32),"-") -> 0.16204453
B33: Other Product COGS | C33: ='Bonchon U.S. P&L'!C29+'Bonchon International P&L'!C43-'Consolidations P&L'!C19 -> -0.0054500074 | D33: ='Bonchon U.S. P&L'!D29+'Bonchon International P&L'!D43-'Consolidations P&L'!D19 -> -0.040312736 | E33: ='Bonchon U.S. P&L'!E29+'Bonchon International P&L'!E43-'Consolidations P&L'!E19 -> 0.30606265 | F33: ='Bonchon U.S. P&L'!F29+'Bonchon International P&L'!F43-'Consolidations P&L'!F19 -> 0.13779985 | G33: ='Bonchon U.S. P&L'!G29+'Bonchon International P&L'!G43-'Consolidations P&L'!G19 -> 0.020230089 | H33: ='Bonchon U.S. P&L'!H29+'Bonchon International P&L'!H43-'Consolidations P&L'!H19 -> 0.014566179 | I33: ='Bonchon U.S. P&L'!I29+'Bonchon International P&L'!I43-'Consolidations P&L'!I19 -> 0.028579146 | J33: ='Bonchon U.S. P&L'!J29+'Bonchon International P&L'!J43-'Consolidations P&L'!J19 -> 0.033588067 | ... L33: ='Bonchon U.S. P&L'!L29+'Bonchon International P&L'!L43-'Consolidations P&L'!L19 -> 0.045372077 | N33: =IFERROR(_xlfn.RRI(4,C33,G33),"-") -> - | O33: =IFERROR(_xlfn.RRI(5,G33,L33),"-") -> 0.17532554
B34: D&A In COGS | C34: ='Bonchon U.S. P&L'!C30+'Bonchon International P&L'!C44-'Consolidations P&L'!C20 -> -0.23105642 | D34: ='Bonchon U.S. P&L'!D30+'Bonchon International P&L'!D44-'Consolidations P&L'!D20 -> -0.18562071 | E34: ='Bonchon U.S. P&L'!E30+'Bonchon International P&L'!E44-'Consolidations P&L'!E20 -> -0.16436635 | F34: ='Bonchon U.S. P&L'!F30+'Bonchon International P&L'!F44-'Consolidations P&L'!F20 -> -0.16295527 | G34: ='Bonchon U.S. P&L'!G30+'Bonchon International P&L'!G44-'Consolidations P&L'!G20 -> -0.14490381 | H34: ='Bonchon U.S. P&L'!H30+'Bonchon International P&L'!H44-'Consolidations P&L'!H20 -> -0.14684124 | I34: ='Bonchon U.S. P&L'!I30+'Bonchon International P&L'!I44-'Consolidations P&L'!I20 -> -0.14684124 | J34: ='Bonchon U.S. P&L'!J30+'Bonchon International P&L'!J44-'Consolidations P&L'!J20 -> -0.14893897 | ... L34: ='Bonchon U.S. P&L'!L30+'Bonchon International P&L'!L44-'Consolidations P&L'!L20 -> -0.14893897 | N34: =IFERROR(_xlfn.RRI(4,C34,G34),"-") -> -0.11010158 | O34: =IFERROR(_xlfn.RRI(5,G34,L34),"-") -> 0.0055084163
B35: Other | C35: =SUM(C33:C34) -> -0.23650643 | D35: =SUM(D33:D34) -> -0.22593345 | E35: =SUM(E33:E34) -> 0.1416963 | F35: =SUM(F33:F34) -> -0.025155423 | G35: =SUM(G33:G34) -> -0.12467372 | H35: =SUM(H33:H34) -> -0.13227506 | I35: =SUM(I33:I34) -> -0.11826209 | J35: =SUM(J33:J34) -> -0.1153509 | ... L35: =SUM(L33:L34) -> -0.10356689 | N35: =IFERROR(_xlfn.RRI(4,C35,G35),"-") -> -0.14791486 | O35: =IFERROR(_xlfn.RRI(5,G35,L35),"-") -> -0.036416828
B36: Total Cost of Goods Sold | C36: =SUM(C31:C32,C35) -> 1.2067122 | D36: =SUM(D31:D32,D35) -> 2.5824061 | E36: =SUM(E31:E32,E35) -> 3.1420585 | F36: =SUM(F31:F32,F35) -> 2.8671791 | G36: =SUM(G31:G32,G35) -> 2.262205 | H36: =SUM(H31:H32,H35) -> 2.4620301 | I36: =SUM(I31:I32,I35) -> 3.1570901 | J36: =SUM(J31:J32,J35) -> 3.5456321 | ... L36: =SUM(L31:L32,L35) -> 4.5556263 | N36: =IFERROR(_xlfn.RRI(4,C36,G36),"-") -> 0.17012448 | O36: =IFERROR(_xlfn.RRI(5,G36,L36),"-") -> 0.15027909
B37: Gross Profit | C37: =C28-C36 -> 19.725981 | D37: =D28-D36 -> 25.024582 | E37: =E28-E36 -> 27.238518 | F37: =F28-F36 -> 27.579201 | G37: =G28-G36 -> 27.398937 | H37: =H28-H36 -> 31.929596 | I37: =I28-I36 -> 41.127396 | J37: =J28-J36 -> 53.974906 | ... L37: =L28-L36 -> 80.322213 | N37: =IFERROR(_xlfn.RRI(4,C37,G37),"-") -> 0.085609844 | O37: =IFERROR(_xlfn.RRI(5,G37,L37),"-") -> 0.23999631
B38: % Margin | C38: =IFERROR(C37/C28,"-") -> 0.94235275 | D38: =IFERROR(D37/D28,"-") -> 0.90645825 | E38: =IFERROR(E37/E28,"-") -> 0.89657673 | F38: =IFERROR(F37/F28,"-") -> 0.90582857 | G38: =IFERROR(G37/G28,"-") -> 0.92373169 | H38: =IFERROR(H37/H28,"-") -> 0.92841193 | I38: =IFERROR(I37/I28,"-") -> 0.92870889 | J38: =IFERROR(J37/J28,"-") -> 0.93835885 | ... L38: =IFERROR(L37/L28,"-") -> 0.94632726
B40: Corporate Labor | C40: ='Bonchon U.S. P&L'!C36+'Bonchon International P&L'!C50-'Consolidations P&L'!C26 -> 5.4884768 | D40: ='Bonchon U.S. P&L'!D36+'Bonchon International P&L'!D50-'Consolidations P&L'!D26 -> 6.3232292 | E40: ='Bonchon U.S. P&L'!E36+'Bonchon International P&L'!E50-'Consolidations P&L'!E26 -> 6.2162056 | F40: ='Bonchon U.S. P&L'!F36+'Bonchon International P&L'!F50-'Consolidations P&L'!F26 -> 6.7169363 | G40: ='Bonchon U.S. P&L'!G36+'Bonchon International P&L'!G50-'Consolidations P&L'!G26 -> 6.9007152 | H40: ='Bonchon U.S. P&L'!H36+'Bonchon International P&L'!H50-'Consolidations P&L'!H26 -> 7.3788678 | I40: ='Bonchon U.S. P&L'!I36+'Bonchon International P&L'!I50-'Consolidations P&L'!I26 -> 8.125476 | J40: ='Bonchon U.S. P&L'!J36+'Bonchon International P&L'!J50-'Consolidations P&L'!J26 -> 9.3177628 | ... L40: ='Bonchon U.S. P&L'!L36+'Bonchon International P&L'!L50-'Consolidations P&L'!L26 -> 11.857117 | N40: =IFERROR(_xlfn.RRI(4,C40,G40),"-") -> 0.058913704 | O40: =IFERROR(_xlfn.RRI(5,G40,L40),"-") -> 0.11433816
B41: Company-Owned Store Labor | C41: ='Bonchon U.S. P&L'!C37+'Bonchon International P&L'!C51-'Consolidations P&L'!C27 -> 0.81641997 | D41: ='Bonchon U.S. P&L'!D37+'Bonchon International P&L'!D51-'Consolidations P&L'!D27 -> 1.8055031 | E41: ='Bonchon U.S. P&L'!E37+'Bonchon International P&L'!E51-'Consolidations P&L'!E27 -> 1.5318652 | F41: ='Bonchon U.S. P&L'!F37+'Bonchon International P&L'!F51-'Consolidations P&L'!F27 -> 1.5250931 | G41: ='Bonchon U.S. P&L'!G37+'Bonchon International P&L'!G51-'Consolidations P&L'!G27 -> 1.2511717 | H41: ='Bonchon U.S. P&L'!H37+'Bonchon International P&L'!H51-'Consolidations P&L'!H27 -> 1.3382442 | I41: ='Bonchon U.S. P&L'!I37+'Bonchon International P&L'!I51-'Consolidations P&L'!I27 -> 1.864387 | J41: ='Bonchon U.S. P&L'!J37+'Bonchon International P&L'!J51-'Consolidations P&L'!J27 -> 2.0379038 | ... L41: ='Bonchon U.S. P&L'!L37+'Bonchon International P&L'!L51-'Consolidations P&L'!L27 -> 2.4345925 | N41: =IFERROR(_xlfn.RRI(4,C41,G41),"-") -> 0.11263014 | O41: =IFERROR(_xlfn.RRI(5,G41,L41),"-") -> 0.14240968
B42: Total Labor | C42: =SUM(C40:C41) -> 6.3048967 | D42: =SUM(D40:D41) -> 8.1287322 | E42: =SUM(E40:E41) -> 7.7480708 | F42: =SUM(F40:F41) -> 8.2420294 | G42: =SUM(G40:G41) -> 8.1518869 | H42: =SUM(H40:H41) -> 8.717112 | I42: =SUM(I40:I41) -> 9.989863 | J42: =SUM(J40:J41) -> 11.355667 | ... L42: =SUM(L40:L41) -> 14.29171 | N42: =IFERROR(_xlfn.RRI(4,C42,G42),"-") -> 0.066338382 | O42: =IFERROR(_xlfn.RRI(5,G42,L42),"-") -> 0.11883285
B43: Marketing Fund | C43: ='Bonchon U.S. P&L'!C39+'Bonchon International P&L'!C53-'Consolidations P&L'!C29 -> 1.7094527 | D43: ='Bonchon U.S. P&L'!D39+'Bonchon International P&L'!D53-'Consolidations P&L'!D29 -> 2.1685849 | E43: ='Bonchon U.S. P&L'!E39+'Bonchon International P&L'!E53-'Consolidations P&L'!E29 -> 2.8156541 | F43: ='Bonchon U.S. P&L'!F39+'Bonchon International P&L'!F53-'Consolidations P&L'!F29 -> 3.2534763 | G43: ='Bonchon U.S. P&L'!G39+'Bonchon International P&L'!G53-'Consolidations P&L'!G29 -> 3.2282713 | H43: ='Bonchon U.S. P&L'!H39+'Bonchon International P&L'!H53-'Consolidations P&L'!H29 -> 4.9917485 | I43: ='Bonchon U.S. P&L'!I39+'Bonchon International P&L'!I53-'Consolidations P&L'!I29 -> 8.5167043 | J43: ='Bonchon U.S. P&L'!J39+'Bonchon International P&L'!J53-'Consolidations P&L'!J29 -> 13.829933 | ... L43: ='Bonchon U.S. P&L'!L39+'Bonchon International P&L'!L53-'Consolidations P&L'!L29 -> 21.009066 | N43: =IFERROR(_xlfn.RRI(4,C43,G43),"-") -> 0.17227159 | O43: =IFERROR(_xlfn.RRI(5,G43,L43),"-") -> 0.45441164
B44: Service Fees | C44: ='Bonchon U.S. P&L'!C40+'Bonchon International P&L'!C54-'Consolidations P&L'!C30 -> 1.5810293 | D44: ='Bonchon U.S. P&L'!D40+'Bonchon International P&L'!D54-'Consolidations P&L'!D30 -> 1.9173266 | E44: ='Bonchon U.S. P&L'!E40+'Bonchon International P&L'!E54-'Consolidations P&L'!E30 -> 2.0300026 | F44: ='Bonchon U.S. P&L'!F40+'Bonchon International P&L'!F54-'Consolidations P&L'!F30 -> 1.8569612 | G44: ='Bonchon U.S. P&L'!G40+'Bonchon International P&L'!G54-'Consolidations P&L'!G30 -> 2.1299289 | H44: ='Bonchon U.S. P&L'!H40+'Bonchon International P&L'!H54-'Consolidations P&L'!H30 -> 2.1977609 | I44: ='Bonchon U.S. P&L'!I40+'Bonchon International P&L'!I54-'Consolidations P&L'!I30 -> 2.4372438 | J44: ='Bonchon U.S. P&L'!J40+'Bonchon International P&L'!J54-'Consolidations P&L'!J30 -> 2.6562904 | ... L44: ='Bonchon U.S. P&L'!L40+'Bonchon International P&L'!L54-'Consolidations P&L'!L30 -> 3.0661305 | N44: =IFERROR(_xlfn.RRI(4,C44,G44),"-") -> 0.077348703 | O44: =IFERROR(_xlfn.RRI(5,G44,L44),"-") -> 0.075585918
B45: Travel & Entertainment | C45: ='Bonchon U.S. P&L'!C41+'Bonchon International P&L'!C55-'Consolidations P&L'!C31 -> 0.37251615 | D45: ='Bonchon U.S. P&L'!D41+'Bonchon International P&L'!D55-'Consolidations P&L'!D31 -> 0.62507617 | E45: ='Bonchon U.S. P&L'!E41+'Bonchon International P&L'!E55-'Consolidations P&L'!E31 -> 0.99585521 | F45: ='Bonchon U.S. P&L'!F41+'Bonchon International P&L'!F55-'Consolidations P&L'!F31 -> 1.0170407 | G45: ='Bonchon U.S. P&L'!G41+'Bonchon International P&L'!G55-'Consolidations P&L'!G31 -> 0.81764289 | H45: ='Bonchon U.S. P&L'!H41+'Bonchon International P&L'!H55-'Consolidations P&L'!H31 -> 1.2534341 | I45: ='Bonchon U.S. P&L'!I41+'Bonchon International P&L'!I55-'Consolidations P&L'!I31 -> 1.3425663 | J45: ='Bonchon U.S. P&L'!J41+'Bonchon International P&L'!J55-'Consolidations P&L'!J31 -> 1.6950299 | ... L45: ='Bonchon U.S. P&L'!L41+'Bonchon International P&L'!L55-'Consolidations P&L'!L31 -> 2.5246005 | N45: =IFERROR(_xlfn.RRI(4,C45,G45),"-") -> 0.21717953 | O45: =IFERROR(_xlfn.RRI(5,G45,L45),"-") -> 0.25292709
B46: Rent | C46: ='Bonchon U.S. P&L'!C42+'Bonchon International P&L'!C56-'Consolidations P&L'!C32 -> 0.50192166 | D46: ='Bonchon U.S. P&L'!D42+'Bonchon International P&L'!D56-'Consolidations P&L'!D32 -> 0.66905733 | E46: ='Bonchon U.S. P&L'!E42+'Bonchon International P&L'!E56-'Consolidations P&L'!E32 -> 0.77520518 | F46: ='Bonchon U.S. P&L'!F42+'Bonchon International P&L'!F56-'Consolidations P&L'!F32 -> 0.73765761 | G46: ='Bonchon U.S. P&L'!G42+'Bonchon International P&L'!G56-'Consolidations P&L'!G32 -> 0.74150514 | H46: ='Bonchon U.S. P&L'!H42+'Bonchon International P&L'!H56-'Consolidations P&L'!H32 -> 0.79208247 | I46: ='Bonchon U.S. P&L'!I42+'Bonchon International P&L'!I56-'Consolidations P&L'!I32 -> 0.90336045 | J46: ='Bonchon U.S. P&L'!J42+'Bonchon International P&L'!J56-'Consolidations P&L'!J32 -> 0.94500754 | ... L46: ='Bonchon U.S. P&L'!L42+'Bonchon International P&L'!L56-'Consolidations P&L'!L32 -> 1.0228392 | N46: =IFERROR(_xlfn.RRI(4,C46,G46),"-") -> 0.10247705 | O46: =IFERROR(_xlfn.RRI(5,G46,L46),"-") -> 0.066445437
B47: Freight | C47: ='Bonchon U.S. P&L'!C43+'Bonchon International P&L'!C57-'Consolidations P&L'!C33 -> 0.69323992 | D47: ='Bonchon U.S. P&L'!D43+'Bonchon International P&L'!D57-'Consolidations P&L'!D33 -> 0.98323817 | E47: ='Bonchon U.S. P&L'!E43+'Bonchon International P&L'!E57-'Consolidations P&L'!E33 -> 0.75590531 | F47: ='Bonchon U.S. P&L'!F43+'Bonchon International P&L'!F57-'Consolidations P&L'!F33 -> 0.56354548 | G47: ='Bonchon U.S. P&L'!G43+'Bonchon International P&L'!G57-'Consolidations P&L'!G33 -> 0.43534247 | H47: ='Bonchon U.S. P&L'!H43+'Bonchon International P&L'!H57-'Consolidations P&L'!H33 -> 0.503025 | I47: ='Bonchon U.S. P&L'!I43+'Bonchon International P&L'!I57-'Consolidations P&L'!I33 -> 0.64097381 | J47: ='Bonchon U.S. P&L'!J43+'Bonchon International P&L'!J57-'Consolidations P&L'!J33 -> 0.69770306 | ... L47: ='Bonchon U.S. P&L'!L43+'Bonchon International P&L'!L57-'Consolidations P&L'!L33 -> 0.82806665 | N47: =IFERROR(_xlfn.RRI(4,C47,G47),"-") -> -0.10980148 | O47: =IFERROR(_xlfn.RRI(5,G47,L47),"-") -> 0.13722619
B48: Advertising Expense | C48: ='Bonchon U.S. P&L'!C44+'Bonchon International P&L'!C58-'Consolidations P&L'!C34 -> 0.15082599 | D48: ='Bonchon U.S. P&L'!D44+'Bonchon International P&L'!D58-'Consolidations P&L'!D34 -> 0.45786222 | E48: ='Bonchon U.S. P&L'!E44+'Bonchon International P&L'!E58-'Consolidations P&L'!E34 -> 0.45619212 | F48: ='Bonchon U.S. P&L'!F44+'Bonchon International P&L'!F58-'Consolidations P&L'!F34 -> 0.50157127 | G48: ='Bonchon U.S. P&L'!G44+'Bonchon International P&L'!G58-'Consolidations P&L'!G34 -> 0.47832907 | H48: ='Bonchon U.S. P&L'!H44+'Bonchon International P&L'!H58-'Consolidations P&L'!H34 -> 0.5741027 | I48: ='Bonchon U.S. P&L'!I44+'Bonchon International P&L'!I58-'Consolidations P&L'!I34 -> 0.85984071 | J48: ='Bonchon U.S. P&L'!J44+'Bonchon International P&L'!J58-'Consolidations P&L'!J34 -> 1.1375016 | ... L48: ='Bonchon U.S. P&L'!L44+'Bonchon International P&L'!L58-'Consolidations P&L'!L34 -> 1.5780826 | N48: =IFERROR(_xlfn.RRI(4,C48,G48),"-") -> 0.33448178 | O48: =IFERROR(_xlfn.RRI(5,G48,L48),"-") -> 0.26963999
...

Sheet Bonchon U.S. P&L
B2: Bonchon U.S. P&L
C4: Historical | H4: Projected | N4: CAGR
B5: ($ in millions) | C5: 2021 | D5: 2022 | E5: 2023 | F5: 2024 | G5: 2025A | H5: 2026E | I5: 2027P | J5: 2028P | K5: 2029P | L5: 2030P | N5: '21A-'25E | O5: '25E-'30P
B7: Franchise Restaurants | C7: ='U.S. Restaurant Count Detail'!C13 -> 111 | D7: ='U.S. Restaurant Count Detail'!D13 -> 117 | E7: ='U.S. Restaurant Count Detail'!E13 -> 127 | F7: ='U.S. Restaurant Count Detail'!F13 -> 143 | G7: ='U.S. Restaurant Count Detail'!G13 -> 148 | H7: ='U.S. Restaurant Count Detail'!H13 -> 175 | I7: ='U.S. Restaurant Count Detail'!I13 -> 205 | J7: ='U.S. Restaurant Count Detail'!J13 -> 240 | ... L7: ='U.S. Restaurant Count Detail'!L13 -> 340 | N7: =IFERROR(_xlfn.RRI(4,C7,G7),"-") -> 0.074569932 | O7: =IFERROR(_xlfn.RRI(5,G7,L7),"-") -> 0.18098244
B8: Company-Owned Restaurants | C8: ='U.S. Restaurant Count Detail'!C19 -> 4 | D8: ='U.S. Restaurant Count Detail'!D19 -> 5 | E8: ='U.S. Restaurant Count Detail'!E19 -> 4 | F8: ='U.S. Restaurant Count Detail'!F19 -> 4 | G8: ='U.S. Restaurant Count Detail'!G19 -> 3 | H8: ='U.S. Restaurant Count Detail'!H19 -> 4 | I8: ='U.S. Restaurant Count Detail'!I19 -> 4 | J8: ='U.S. Restaurant Count Detail'!J19 -> 4 | ... L8: ='U.S. Restaurant Count Detail'!L19 -> 4 | N8: =IFERROR(_xlfn.RRI(4,C8,G8),"-") -> -0.069395141 | O8: =IFERROR(_xlfn.RRI(5,G8,L8),"-") -> 0.059223841
B9: Total Restaurants | C9: =SUM(C7:C8) -> 115 | D9: =SUM(D7:D8) -> 122 | E9: =SUM(E7:E8) -> 131 | F9: =SUM(F7:F8) -> 147 | G9: =SUM(G7:G8) -> 151 | H9: =SUM(H7:H8) -> 179 | I9: =SUM(I7:I8) -> 209 | J9: =SUM(J7:J8) -> 244 | ... L9: =SUM(L7:L8) -> 344 | N9: =IFERROR(_xlfn.RRI(4,C9,G9),"-") -> 0.070458356 | O9: =IFERROR(_xlfn.RRI(5,G9,L9),"-") -> 0.17900677
B10: % Growth | D10: =IFERROR(D9/C9-1,0) -> 0.060869565 | E10: =IFERROR(E9/D9-1,0) -> 0.073770492 | F10: =IFERROR(F9/E9-1,0) -> 0.1221374 | G10: =IFERROR(G9/F9-1,0) -> 0.027210884 | H10: =IFERROR(H9/G9-1,0) -> 0.18543046 | I10: =IFERROR(I9/H9-1,0) -> 0.16759777 | J10: =IFERROR(J9/I9-1,0) -> 0.16746411 | K10: =IFERROR(K9/J9-1,0) -> 0.18442623 | L10: =IFERROR(L9/K9-1,0) -> 0.19031142
B12: Systemwide Sales | C12: ='U.S. Restaurant Count Detail'!C31 -> 173.415 | D12: ='U.S. Restaurant Count Detail'!D31 -> 193.64356 | E12: ='U.S. Restaurant Count Detail'!E31 -> 200.67402 | F12: ='U.S. Restaurant Count Detail'!F31 -> 202.35598 | G12: 211.07983 | H12: ='U.S. Restaurant Count Detail'!H31 -> 236.36305 | I12: ='U.S. Restaurant Count Detail'!I31 -> 290.17861 | J12: ='U.S. Restaurant Count Detail'!J31 -> 352.66562 | K12: ='U.S. Restaurant Count Detail'!K31 -> 431.83056 | L12: ='U.S. Restaurant Count Detail'!L31 -> 533.59659 | N12: =IFERROR(_xlfn.RRI(4,C12,G12),"-") -> 0.050364462 | O12: =IFERROR(_xlfn.RRI(5,G12,L12),"-") -> 0.20379702
B13: % Growth | D13: =IFERROR(D12/C12-1,0) -> 0.1166483 | E13: =IFERROR(E12/D12-1,0) -> 0.036306147 | F13: =IFERROR(F12/E12-1,0) -> 0.0083815659 | G13: =IFERROR(G12/F12-1,0) -> 0.043111413 | H13: =IFERROR(H12/G12-1,0) -> 0.11978035 | I13: =IFERROR(I12/H12-1,0) -> 0.22768178 | J13: =IFERROR(J12/I12-1,0) -> 0.21533984 | K13: =IFERROR(K12/J12-1,0) -> 0.22447593 | L13: =IFERROR(L12/K12-1,0) -> 0.23566194
B15: U.S. Same Store Sales | C15: 0.16753805 | D15: 0.049974743 | E15: -0.033246735 | F15: -0.079297458 | G15: 8.3373689e-05 | H15: ='U.S. Franchise Sales & Dev'!D14 -> 0.05043868 | I15: ='U.S. Franchise Sales & Dev'!E14 -> 0.04 | J15: ='U.S. Franchise Sales & Dev'!F14 -> 0.04 | K15: ='U.S. Franchise Sales & Dev'!G14 -> 0.04 | L15: ='U.S. Franchise Sales & Dev'!H14 -> 0.04
B17: Franchise Revenue | C17: 8.4856376 | D17: 9.2181573 | E17: 9.8702525 | F17: 9.8424246 | G17: =SUM('Bonchon U.S. P&L (Monthly''25)'!C7:N7) -> 10.201735 | H17: =SUM('Bonchon U.S. P&L (Monthly''26)'!C7:N7) -> 11.624896 | I17: ='U.S. Franchise Sales & Dev'!E36 -> 13.864917 | J17: ='U.S. Franchise Sales & Dev'!F36 -> 18.229997 | K17: ='U.S. Franchise Sales & Dev'!G36 -> 22.455913 | L17: ='U.S. Franchise Sales & Dev'!H36 -> 27.847593 | N17: =IFERROR(_xlfn.RRI(4,C17,G17),"-") -> 0.047122246 | O17: =IFERROR(_xlfn.RRI(5,G17,L17),"-") -> 0.22242642
B18: Sauce Revenue | C18: 1.5092535 | D18: 1.7763786 | E18: 3.0626712 | F18: 2.7871825 | G18: =SUM('Bonchon U.S. P&L (Monthly''25)'!C8:N8) -> 2.351576 | H18: =SUM('Bonchon U.S. P&L (Monthly''26)'!C8:N8) -> 2.6228589 | I18: ='Sauce Economics Overview'!I33 -> 2.8194106 | J18: ='Sauce Economics Overview'!J33 -> 3.500338 | K18: ='Sauce Economics Overview'!K33 -> 5.2782141 | L18: ='Sauce Economics Overview'!L33 -> 6.6315479 | N18: =IFERROR(_xlfn.RRI(4,C18,G18),"-") -> 0.11724703 | O18: =IFERROR(_xlfn.RRI(5,G18,L18),"-") -> 0.23041376
B19: Company-Owned Store Revenue | C19: 1.7976949 | D19: 5.1372586 | E19: 5.0760827 | F19: 4.1612575 | G19: =SUM('Bonchon U.S. P&L (Monthly''25)'!C9:N9) -> 3.7884491 | H19: =SUM('Bonchon U.S. P&L (Monthly''26)'!C9:N9) -> 4.3374481 | I19: ='Company-Owned Store Detail'!E21+'Company-Owned Store Detail'!E22 -> 6.2884611 | J19: ='Company-Owned Store Detail'!F21+'Company-Owned Store Detail'!F22 -> 6.9173072 | K19: ='Company-Owned Store Detail'!G21+'Company-Owned Store Detail'!G22 -> 7.6090379 | L19: ='Company-Owned Store Detail'!H21+'Company-Owned Store Detail'!H22 -> 8.3699417 | N19: =IFERROR(_xlfn.RRI(4,C19,G19),"-") -> 0.20485939 | O19: =IFERROR(_xlfn.RRI(5,G19,L19),"-") -> 0.17179649
B20: Marketing Fund | C20: 1.7094527 | D20: 2.1685849 | E20: 2.8156541 | F20: 3.2534763 | G20: =SUM('Bonchon U.S. P&L (Monthly''25)'!C10:N10) -> 3.2282713 | H20: =SUM('Bonchon U.S. P&L (Monthly''26)'!C10:N10) -> 4.9917485 | I20: ='U.S. Franchise Sales & Dev'!E44 -> 8.5167043 | J20: ='U.S. Franchise Sales & Dev'!F44 -> 13.829933 | K20: ='U.S. Franchise Sales & Dev'!G44 -> 16.968861 | L20: ='U.S. Franchise Sales & Dev'!H44 -> 21.009066 | N20: =IFERROR(_xlfn.RRI(4,C20,G20),"-") -> 0.17227159 | O20: =IFERROR(_xlfn.RRI(5,G20,L20),"-") -> 0.45441164
B21: Other Product Revenue | C21: -0.08183353 | D21: -0.10277591 | E21: 0.34332006 | F21: 0.12552208 | G21: =SUM('Bonchon U.S. P&L (Monthly''25)'!C11:N11) -> -0.01468906 | H21: =SUM('Bonchon U.S. P&L (Monthly''26)'!C11:N11) -> 0.00954 | I21: ='Sauce Economics Overview'!I41 -> 0.011789964 | J21: ='Sauce Economics Overview'!J41 -> 0.01407253 | K21: ='Sauce Economics Overview'!K41 -> 0.016952911 | L21: ='Sauce Economics Overview'!L41 -> 0.020631851 | N21: =IFERROR(_xlfn.RRI(4,C21,G21),"-") -> -0.34909789 | O21: =IFERROR(_xlfn.RRI(5,G21,L21),"-") -> -
B22: Other Revenue | C22: 0.30773293 | D22: 0.12628718 | E22: 0.27595889 | F22: 0.1570314 | G22: =SUM('Bonchon U.S. P&L (Monthly''25)'!C12:N12) -> 0.17322978 | H22: =SUM('Bonchon U.S. P&L (Monthly''26)'!C12:N12) -> 0.20392759 | I22: ='U.S. Franchise Sales & Dev'!E40 -> 0.2275 | J22: ='U.S. Franchise Sales & Dev'!F40 -> 0.26 | K22: ='U.S. Franchise Sales & Dev'!G40 -> 0.325 | L22: ='U.S. Franchise Sales & Dev'!H40 -> 0.39 | N22: =IFERROR(_xlfn.RRI(4,C22,G22),"-") -> -0.13381203 | O22: =IFERROR(_xlfn.RRI(5,G22,L22),"-") -> 0.1762196
B23: Other | C23: =SUM(C21:C22) -> 0.2258994 | D23: =SUM(D21:D22) -> 0.02351127 | E23: =SUM(E21:E22) -> 0.61927895 | F23: =SUM(F21:F22) -> 0.28255348 | G23: =SUM(G21:G22) -> 0.15854072 | H23: =SUM(H21:H22) -> 0.21346759 | I23: =SUM(I21:I22) -> 0.23928996 | J23: =SUM(J21:J22) -> 0.27407253 | ... L23: =SUM(L21:L22) -> 0.41063185 | N23: =IFERROR(_xlfn.RRI(4,C23,G23),"-") -> -0.084714806 | O23: =IFERROR(_xlfn.RRI(5,G23,L23),"-") -> 0.20965733
B24: Total Revenue | C24: =SUM(C17:C20,C23) -> 13.727938 | D24: =SUM(D17:D20,D23) -> 18.323891 | E24: =SUM(E17:E20,E23) -> 21.443939 | F24: =SUM(F17:F20,F23) -> 20.326894 | G24: =SUM(G17:G20,G23) -> 19.728572 | H24: =SUM(H17:H20,H23) -> 23.790419 | I24: =SUM(I17:I20,I23) -> 31.728783 | J24: =SUM(J17:J20,J23) -> 42.751647 | ... L24: =SUM(L17:L20,L23) -> 64.268781 | N24: =IFERROR(_xlfn.RRI(4,C24,G24),"-") -> 0.094895282 | O24: =IFERROR(_xlfn.RRI(5,G24,L24),"-") -> 0.2664291
B25: % Growth | D25: =IFERROR(D24/C24-1,0) -> 0.33478826 | E25: =IFERROR(E24/D24-1,0) -> 0.17027218 | F25: =IFERROR(F24/E24-1,0) -> -0.052091411 | G25: =IFERROR(G24/F24-1,0) -> -0.029435015 | H25: =IFERROR(H24/G24-1,0) -> 0.20588652 | I25: =IFERROR(I24/H24-1,0) -> 0.33367903 | J25: =IFERROR(J24/I24-1,0) -> 0.34740897 | K25: =IFERROR(K24/J24-1,0) -> 0.23162457 | L25: =IFERROR(L24/K24-1,0) -> 0.22058736
B27: Sauce COGS | C27: ='Sauce Economics Overview'!C34 -> 0.0009373 | D27: ='Sauce Economics Overview'!D34 -> 0.03314327 | E27: ='Sauce Economics Overview'!E34 -> 0.22863007 | F27: ='Sauce Economics Overview'!F34 -> 0.12063587 | G27: =SUM('Bonchon U.S. P&L (Monthly''25)'!C16:N16) -> 0.01355097 | H27: =SUM('Bonchon U.S. P&L (Monthly''26)'!C16:N16) -> 0 | I27: ='Sauce Economics Overview'!I34 -> 0 | J27: ='Sauce Economics Overview'!J34 -> 0 | K27: ='Sauce Economics Overview'!K34 -> 0 | L27: ='Sauce Economics Overview'!L34 -> 0 | N27: =IFERROR(_xlfn.RRI(4,C27,G27),"-") -> 0.9499476 | O27: =IFERROR(_xlfn.RRI(5,G27,L27),"-") -> -1
B28: Company-Owned Store COGS | C28: 0.57564599 | D28: 1.5265284 | E28: 1.4018693 | F28: 1.4141352 | G28: =SUM('Bonchon U.S. P&L (Monthly''25)'!C17:N17) -> 1.0689561 | H28: =SUM('Bonchon U.S. P&L (Monthly''26)'!C17:N17) -> 1.2437544 | I28: ='Company-Owned Store Detail'!E36+'Company-Owned Store Detail'!E68 -> 1.7413943 | J28: ='Company-Owned Store Detail'!F36+'Company-Owned Store Detail'!F68 -> 1.8960876 | K28: ='Company-Owned Store Detail'!G36+'Company-Owned Store Detail'!G68 -> 2.0805078 | L28: ='Company-Owned Store Detail'!H36+'Company-Owned Store Detail'!H68 -> 2.2650287 | N28: =IFERROR(_xlfn.RRI(4,C28,G28),"-") -> 0.16735002 | O28: =IFERROR(_xlfn.RRI(5,G28,L28),"-") -> 0.16204453
B29: Other Product COGS | C29: 0.0324647 | D29: 0.02571077 | E29: 0.30932278 | F29: 0.12200699 | G29: =SUM('Bonchon U.S. P&L (Monthly''25)'!C18:N18) -> 0.01238843 | H29: =SUM('Bonchon U.S. P&L (Monthly''26)'!C18:N18) -> 0.0057487721 | I29: ='Sauce Economics Overview'!I42 -> 0.0071045931 | J29: ='Sauce Economics Overview'!J42 -> 0.0084800596 | K29: ='Sauce Economics Overview'!K42 -> 0.010215767 | L29: ='Sauce Economics Overview'!L42 -> 0.012432684 | N29: =IFERROR(_xlfn.RRI(4,C29,G29),"-") -> -0.2140386 | O29: =IFERROR(_xlfn.RRI(5,G29,L29),"-") -> 0.00071342788
B30: D&A In COGS | C30: 0 | D30: 0 | E30: 0 | F30: 0 | G30: =SUM('Bonchon U.S. P&L (Monthly''26)'!B19:M19) -> 0 | H30: =SUM('Bonchon U.S. P&L (Monthly''26)'!C19:N19) -> 0 | I30: 0 | J30: 0 | K30: 0 | L30: 0 | N30: =IFERROR(_xlfn.RRI(4,C30,G30),"-") -> 0 | O30: =IFERROR(_xlfn.RRI(5,G30,L30),"-") -> 0
B31: Other | C31: =SUM(C29:C30) -> 0.0324647 | D31: =SUM(D29:D30) -> 0.02571077 | E31: =SUM(E29:E30) -> 0.30932278 | F31: =SUM(F29:F30) -> 0.12200699 | G31: =SUM(G29:G30) -> 0.01238843 | H31: =SUM(H29:H30) -> 0.0057487721 | I31: =SUM(I29:I30) -> 0.0071045931 | J31: =SUM(J29:J30) -> 0.0084800596 | ... L31: =SUM(L29:L30) -> 0.012432684 | N31: =IFERROR(_xlfn.RRI(4,C31,G31),"-") -> -0.2140386 | O31: =IFERROR(_xlfn.RRI(5,G31,L31),"-") -> 0.00071342788
B32: Total Cost of Goods Sold | C32: =SUM(C27:C28,C31) -> 0.60904799 | D32: =SUM(D27:D28,D31) -> 1.5853825 | E32: =SUM(E27:E28,E31) -> 1.9398222 | F32: =SUM(F27:F28,F31) -> 1.6567781 | G32: =SUM(G27:G28,G31) -> 1.0948955 | H32: =SUM(H27:H28,H31) -> 1.2495032 | I32: =SUM(I27:I28,I31) -> 1.7484989 | J32: =SUM(J27:J28,J31) -> 1.9045676 | ... L32: =SUM(L27:L28,L31) -> 2.2774614 | N32: =IFERROR(_xlfn.RRI(4,C32,G32),"-") -> 0.15792462 | O32: =IFERROR(_xlfn.RRI(5,G32,L32),"-") -> 0.15775235
B33: Gross Profit | C33: =C24-C32 -> 13.11889 | D33: =D24-D32 -> 16.738508 | E33: =E24-E32 -> 19.504117 | F33: =F24-F32 -> 18.670116 | G33: =G24-G32 -> 18.633676 | H33: =H24-H32 -> 22.540916 | I33: =I24-I32 -> 29.980284 | J33: =J24-J32 -> 40.847079 | ... L33: =L24-L32 -> 61.99132 | N33: =IFERROR(_xlfn.RRI(4,C33,G33),"-") -> 0.091692594 | O33: =IFERROR(_xlfn.RRI(5,G33,L33),"-") -> 0.27176382
B34: % Margin | C34: =IFERROR(C33/C24,"-") -> 0.95563442 | D34: =IFERROR(D33/D24,"-") -> 0.91348003 | E34: =IFERROR(E33/E24,"-") -> 0.90953984 | F34: =IFERROR(F33/F24,"-") -> 0.9184933 | G34: =IFERROR(G33/G24,"-") -> 0.94450204 | H34: =IFERROR(H33/H24,"-") -> 0.94747872 | I34: =IFERROR(I33/I24,"-") -> 0.94489234 | J34: =IFERROR(J33/J24,"-") -> 0.95545043 | ... L34: =IFERROR(L33/L24,"-") -> 0.96456349
B36: Corporate Labor | C36: =(4.9932962429754)-0.81641997 -> 4.1768763 | D36: 5.139958 | E36: 5.3966265 | F36: 5.5795328 | G36: =SUM('Bonchon U.S. P&L (Monthly''25)'!C25:N25) -> 5.6734943 | H36: =SUM('Bonchon U.S. P&L (Monthly''26)'!C25:N25) -> 6.0878854 | I36: ='U.S. SG&A'!I17 -> 6.6813384 | J36: ='U.S. SG&A'!J17 -> 7.7123117 | K36: ='U.S. SG&A'!K17 -> 8.7158088 | L36: ='U.S. SG&A'!L17 -> 9.9223485 | N36: =IFERROR(_xlfn.RRI(4,C38,G38),"-") -> 0.08518273 | O36: =IFERROR(_xlfn.RRI(5,G38,L38),"-") -> 0.12280006
B37: Company-Owned Store Labor | C37: 0.81641997 | D37: 1.8055031 | E37: 1.5318652 | F37: 1.5250931 | G37: =SUM('Bonchon U.S. P&L (Monthly''25)'!C26:N26) -> 1.2511717 | H37: =SUM('Bonchon U.S. P&L (Monthly''26)'!C26:N26) -> 1.3382442 | I37: ='Company-Owned Store Detail'!E40+'Company-Owned Store Detail'!E72 -> 1.864387 | J37: ='Company-Owned Store Detail'!F40+'Company-Owned Store Detail'!F72 -> 2.0379038 | K37: ='Company-Owned Store Detail'!G40+'Company-Owned Store Detail'!G72 -> 2.22748 | L37: ='Company-Owned Store Detail'!H40+'Company-Owned Store Detail'!H72 -> 2.4345925 | N37: =IFERROR(_xlfn.RRI(4,C39,G39),"-") -> 0.17227159 | O37: =IFERROR(_xlfn.RRI(5,G39,L39),"-") -> 0.45441164
B38: Total Labor | C38: =SUM(C36:C37) -> 4.9932962 | D38: =SUM(D36:D37) -> 6.9454611 | E38: =SUM(E36:E37) -> 6.9284917 | F38: =SUM(F36:F37) -> 7.1046259 | G38: =SUM(G36:G37) -> 6.924666 | H38: =SUM(H36:H37) -> 7.4261296 | I38: =SUM(I36:I37) -> 8.5457254 | J38: =SUM(J36:J37) -> 9.7502155 | ... L38: =SUM(L36:L37) -> 12.356941 | N38: =IFERROR(_xlfn.RRI(4,C40,G40),"-") -> 0.09422476 | O38: =IFERROR(_xlfn.RRI(5,G40,L40),"-") -> 0.079570638
B39: Marketing Fund | C39: =C20 -> 1.7094527 | D39: =D20 -> 2.1685849 | E39: =E20 -> 2.8156541 | F39: =F20 -> 3.2534763 | G39: =SUM('Bonchon U.S. P&L (Monthly''25)'!C28:N28) -> 3.2282713 | H39: =H20 -> 4.9917485 | I39: =I20 -> 8.5167043 | J39: =J20 -> 13.829933 | K39: =K20 -> 16.968861 | L39: =L20 -> 21.009066 | N39: =IFERROR(_xlfn.RRI(4,C39,G39),"-") -> 0.17227159 | O39: =IFERROR(_xlfn.RRI(5,G39,L39),"-") -> 0.45441164
B40: Service Fees | C40: 1.2327444 | D40: 1.6513941 | E40: 1.7693728 | F40: 1.6195792 | G40: =SUM('Bonchon U.S. P&L (Monthly''25)'!C29:N29) -> 1.7672548 | H40: =SUM('Bonchon U.S. P&L (Monthly''26)'!C29:N29) -> 1.8172835 | I40: ='U.S. SG&A'!I19+'Company-Owned Store Detail'!E42+'Company-Owned Store Detail'!E74 -> 2.0332062 | J40: ='U.S. SG&A'!J19+'Company-Owned Store Detail'!F42+'Company-Owned Store Detail'!F74 -> 2.2294639 | K40: ='U.S. SG&A'!K19+'Company-Owned Store Detail'!G42+'Company-Owned Store Detail'!G74 -> 2.4034682 | L40: ='U.S. SG&A'!L19+'Company-Owned Store Detail'!H42+'Company-Owned Store Detail'!H74 -> 2.5915196 | N40: =IFERROR(_xlfn.RRI(4,C40,G40),"-") -> 0.09422476 | O40: =IFERROR(_xlfn.RRI(5,G40,L40),"-") -> 0.079570638
B41: Travel & Entertainment | C41: 0.30548267 | D41: 0.44892336 | E41: 0.63691371 | F41: 0.69853945 | G41: =SUM('Bonchon U.S. P&L (Monthly''25)'!C30:N30) -> 0.6301413 | H41: =SUM('Bonchon U.S. P&L (Monthly''26)'!C30:N30) -> 0.98442005 | I41: ='U.S. SG&A'!I20+'Company-Owned Store Detail'!E48 -> 0.99505803 | J41: ='U.S. SG&A'!J20+'Company-Owned Store Detail'!F48 -> 1.2862873 | K41: ='U.S. SG&A'!K20+'Company-Owned Store Detail'!G48 -> 1.5770858 | L41: ='U.S. SG&A'!L20+'Company-Owned Store Detail'!H48 -> 1.9542553 | N41: =IFERROR(_xlfn.RRI(4,C41,G41),"-") -> 0.19843047 | O41: =IFERROR(_xlfn.RRI(5,G41,L41),"-") -> 0.25403215
B42: Rent | C42: 0.3899499 | D42: 0.5677604 | E42: 0.6716284 | F42: 0.61910609 | G42: =SUM('Bonchon U.S. P&L (Monthly''25)'!C31:N31) -> 0.62726085 | H42: =SUM('Bonchon U.S. P&L (Monthly''26)'!C31:N31) -> 0.67419975 | I42: ='U.S. SG&A'!I21+'Company-Owned Store Detail'!E44 -> 0.78091388 | J42: ='U.S. SG&A'!J21+'Company-Owned Store Detail'!F44 -> 0.81831287 | K42: ='U.S. SG&A'!K21+'Company-Owned Store Detail'!G44 -> 0.85133105 | L42: ='U.S. SG&A'!L21+'Company-Owned Store Detail'!H44 -> 0.88756633 | N42: =IFERROR(_xlfn.RRI(4,C42,G42),"-") -> 0.12618527 | O42: =IFERROR(_xlfn.RRI(5,G42,L42),"-") -> 0.071890761
B43: Freight | C43: 0.67884456 | D43: 0.96982432 | E43: 0.74838686 | F43: 0.54956246 | G43: =SUM('Bonchon U.S. P&L (Monthly''25)'!C32:N32) -> 0.426513 | H43: =SUM('Bonchon U.S. P&L (Monthly''26)'!C32:N32) -> 0.49288415 | I43: ='U.S. SG&A'!I22+'Company-Owned Store Detail'!E46+'Company-Owned Store Detail'!E78 -> 0.62787402 | J43: ='U.S. SG&A'!J22+'Company-Owned Store Detail'!F46+'Company-Owned Store Detail'!F78 -> 0.68229496 | K43: ='U.S. SG&A'!K22+'Company-Owned Store Detail'!G46+'Company-Owned Store Detail'!G78 -> 0.74131975 | L43: ='U.S. SG&A'!L22+'Company-Owned Store Detail'!H46+'Company-Owned Store Detail'!H78 -> 0.80656673 | N43: =IFERROR(_xlfn.RRI(4,C43,G43),"-") -> -0.10969158 | O43: =IFERROR(_xlfn.RRI(5,G43,L43),"-") -> 0.13590394
B44: Advertising Expense | C44: 0.14672548 | D44: 0.2688334 | E44: 0.38128166 | F44: 0.44761616 | G44: =SUM('Bonchon U.S. P&L (Monthly''25)'!C33:N33) -> 0.44908484 | H44: =SUM('Bonchon U.S. P&L (Monthly''26)'!C33:N33) -> 0.55720129 | I44: ='U.S. SG&A'!I23+'Company-Owned Store Detail'!E50+'Company-Owned Store Detail'!E82 -> 0.79637898 | J44: ='U.S. SG&A'!J23+'Company-Owned Store Detail'!F50+'Company-Owned Store Detail'!F82 -> 1.0629397 | K44: ='U.S. SG&A'!K23+'Company-Owned Store Detail'!G50+'Company-Owned Store Detail'!G82 -> 1.2536412 | L44: ='U.S. SG&A'!L23+'Company-Owned Store Detail'!H50+'Company-Owned Store Detail'!H82 -> 1.4742464 | N44: =IFERROR(_xlfn.RRI(4,C44,G44),"-") -> 0.32268282 | O44: =IFERROR(_xlfn.RRI(5,G44,L44),"-") -> 0.26837694
B45: Other | C45: 0.49172948 | D45: 0.82281255 | E45: 0.79861605 | F45: 0.86382923 | G45: =SUM('Bonchon U.S. P&L (Monthly''25)'!C34:N34) -> 0.81988274 | H45: =SUM('Bonchon U.S. P&L (Monthly''26)'!C34:N34) -> 0.9874354 | I45: ='U.S. SG&A'!I24+'Company-Owned Store Detail'!E52+'Company-Owned Store Detail'!E84 -> 1.0903767 | J45: ='U.S. SG&A'!J24+'Company-Owned Store Detail'!F52+'Company-Owned Store Detail'!F84 -> 1.2648517 | K45: ='U.S. SG&A'!K24+'Company-Owned Store Detail'!G52+'Company-Owned Store Detail'!G84 -> 1.5085243 | L45: ='U.S. SG&A'!L24+'Company-Owned Store Detail'!H52+'Company-Owned Store Detail'!H84 -> 1.7813147 | N45: =IFERROR(_xlfn.RRI(4,C45,G45),"-") -> 0.13633498 | O45: =IFERROR(_xlfn.RRI(5,G45,L45),"-") -> 0.16787881
B46: SG&A | C46: =SUM(C38:C45) -> 9.9482253 | D46: =SUM(D38:D45) -> 13.843594 | E46: =SUM(E38:E45) -> 14.750345 | F46: =SUM(F38:F45) -> 15.156335 | G46: =SUM(G38:G45) -> 14.873075 | H46: =SUM(H38:H45) -> 17.931302 | I46: =SUM(I38:I45) -> 23.386237 | J46: =SUM(J38:J45) -> 30.924298 | ... L46: =SUM(L38:L45) -> 42.861476 | N46: =IFERROR(_xlfn.RRI(4,C46,G46),"-") -> 0.10576741 | O46: =IFERROR(_xlfn.RRI(5,G46,L46),"-") -> 0.23575755
B47: % of Revenue | C47: =IFERROR(C46/C24,"-") -> 0.72467003 | D47: =IFERROR(D46/D24,"-") -> 0.75549426 | E47: =IFERROR(E46/E24,"-") -> 0.68785613 | F47: =IFERROR(F46/F24,"-") -> 0.74562963 | G47: =IFERROR(G46/G24,"-") -> 0.75388502 | H47: =IFERROR(H46/H24,"-") -> 0.75371948 | I47: =IFERROR(I46/I24,"-") -> 0.73706696 | J47: =IFERROR(J46/J24,"-") -> 0.72334754 | ... L47: =IFERROR(L46/L24,"-") -> 0.66690974
B49: Adj. EBITDA | C49: =C33-C46 -> 3.1706648 | D49: =D33-D46 -> 2.894914 | E49: =E33-E46 -> 4.753772 | F49: =F33-F46 -> 3.5137815 | G49: =G33-G46 -> 3.7606016 | H49: =H33-H46 -> 4.6096135 | I49: =I33-I46 -> 6.5940465 | J49: =J33-J46 -> 9.9227807 | ... L49: =L33-L46 -> 19.129844 | N49: =IFERROR(_xlfn.RRI(4,C49,G49),"-") -> 0.04358241 | O49: =IFERROR(_xlfn.RRI(5,G49,L49),"-") -> 0.38449317
...

Sheet Bonchon International P&L
B2: Bonchon International P&L
C4: Historical | H4: Projected | N4: CAGR
B5: ($ in millions) | C5: 2021 | D5: 2022 | E5: 2023 | F5: 2024 | G5: 2025A | H5: 2026E | I5: 2027P | J5: 2028P | K5: 2029P | L5: 2030P | N5: '21A-'25E | O5: '25E-'30P
B7: Philippines | C7: =_xlfn.XLOOKUP($B7,'INTL Restaurant Count Detail'!$B:$B,'INTL Restaurant Count Detail'!D:D) -> 144 | D7: =_xlfn.XLOOKUP($B7,'INTL Restaurant Count Detail'!$B:$B,'INTL Restaurant Count Detail'!E:E) -> 139 | E7: =_xlfn.XLOOKUP($B7,'INTL Restaurant Count Detail'!$B:$B,'INTL Restaurant Count Detail'!F:F) -> 149 | F7: =_xlfn.XLOOKUP($B7,'INTL Restaurant Count Detail'!$B:$B,'INTL Restaurant Count Detail'!G:G) -> 153 | G7: =_xlfn.XLOOKUP($B7,'INTL Restaurant Count Detail'!$B:$B,'INTL Restaurant Count Detail'!H:H) -> 157 | H7: =_xlfn.XLOOKUP($B7,'INTL Restaurant Count Detail'!$B:$B,'INTL Restaurant Count Detail'!I:I) -> 167 | I7: =_xlfn.XLOOKUP($B7,'INTL Restaurant Count Detail'!$B:$B,'INTL Restaurant Count Detail'!J:J) -> 177 | J7: =_xlfn.XLOOKUP($B7,'INTL Restaurant Count Detail'!$B:$B,'INTL Restaurant Count Detail'!K:K) -> 187 | K7: =_xlfn.XLOOKUP($B7,'INTL Restaurant Count Detail'!$B:$B,'INTL Restaurant Count Detail'!L:L) -> 197 | L7: =_xlfn.XLOOKUP($B7,'INTL Restaurant Count Detail'!$B:$B,'INTL Restaurant Count Detail'!M:M) -> 207 | N7: =IFERROR(_xlfn.RRI(4,C7,G7),"-") -> 0.021843273 | O7: =IFERROR(_xlfn.RRI(5,G7,L7),"-") -> 0.056851915
B8: Thailand | C8: =_xlfn.XLOOKUP($B8,'INTL Restaurant Count Detail'!$B:$B,'INTL Restaurant Count Detail'!D:D) -> 101 | D8: =_xlfn.XLOOKUP($B8,'INTL Restaurant Count Detail'!$B:$B,'INTL Restaurant Count Detail'!E:E) -> 112 | E8: =_xlfn.XLOOKUP($B8,'INTL Restaurant Count Detail'!$B:$B,'INTL Restaurant Count Detail'!F:F) -> 118 | F8: =_xlfn.XLOOKUP($B8,'INTL Restaurant Count Detail'!$B:$B,'INTL Restaurant Count Detail'!G:G) -> 122 | G8: =_xlfn.XLOOKUP($B8,'INTL Restaurant Count Detail'!$B:$B,'INTL Restaurant Count Detail'!H:H) -> 134 | H8: =_xlfn.XLOOKUP($B8,'INTL Restaurant Count Detail'!$B:$B,'INTL Restaurant Count Detail'!I:I) -> 138 | I8: =_xlfn.XLOOKUP($B8,'INTL Restaurant Count Detail'!$B:$B,'INTL Restaurant Count Detail'!J:J) -> 146 | J8: =_xlfn.XLOOKUP($B8,'INTL Restaurant Count Detail'!$B:$B,'INTL Restaurant Count Detail'!K:K) -> 157 | K8: =_xlfn.XLOOKUP($B8,'INTL Restaurant Count Detail'!$B:$B,'INTL Restaurant Count Detail'!L:L) -> 171 | L8: =_xlfn.XLOOKUP($B8,'INTL Restaurant Count Detail'!$B:$B,'INTL Restaurant Count Detail'!M:M) -> 188 | N8: =IFERROR(_xlfn.RRI(4,C8,G8),"-") -> 0.073237542 | O8: =IFERROR(_xlfn.RRI(5,G8,L8),"-") -> 0.070066111
B9: Vietnam | C9: =_xlfn.XLOOKUP($B9,'INTL Restaurant Count Detail'!$B:$B,'INTL Restaurant Count Detail'!D:D) -> 6 | D9: =_xlfn.XLOOKUP($B9,'INTL Restaurant Count Detail'!$B:$B,'INTL Restaurant Count Detail'!E:E) -> 11 | E9: =_xlfn.XLOOKUP($B9,'INTL Restaurant Count Detail'!$B:$B,'INTL Restaurant Count Detail'!F:F) -> 14 | F9: =_xlfn.XLOOKUP($B9,'INTL Restaurant Count Detail'!$B:$B,'INTL Restaurant Count Detail'!G:G) -> 24 | G9: =_xlfn.XLOOKUP($B9,'INTL Restaurant Count Detail'!$B:$B,'INTL Restaurant Count Detail'!H:H) -> 26 | H9: =_xlfn.XLOOKUP($B9,'INTL Restaurant Count Detail'!$B:$B,'INTL Restaurant Count Detail'!I:I) -> 33 | I9: =_xlfn.XLOOKUP($B9,'INTL Restaurant Count Detail'!$B:$B,'INTL Restaurant Count Detail'!J:J) -> 39 | J9: =_xlfn.XLOOKUP($B9,'INTL Restaurant Count Detail'!$B:$B,'INTL Restaurant Count Detail'!K:K) -> 45 | K9: =_xlfn.XLOOKUP($B9,'INTL Restaurant Count Detail'!$B:$B,'INTL Restaurant Count Detail'!L:L) -> 51 | L9: =_xlfn.XLOOKUP($B9,'INTL Restaurant Count Detail'!$B:$B,'INTL Restaurant Count Detail'!M:M) -> 57 | N9: =IFERROR(_xlfn.RRI(4,C9,G9),"-") -> 0.44279798 | O9: =IFERROR(_xlfn.RRI(5,G9,L9),"-") -> 0.16998502
B10: Cambodia | C10: =_xlfn.XLOOKUP($B10,'INTL Restaurant Count Detail'!$B:$B,'INTL Restaurant Count Detail'!D:D) -> 11 | D10: =_xlfn.XLOOKUP($B10,'INTL Restaurant Count Detail'!$B:$B,'INTL Restaurant Count Detail'!E:E) -> 11 | E10: =_xlfn.XLOOKUP($B10,'INTL Restaurant Count Detail'!$B:$B,'INTL Restaurant Count Detail'!F:F) -> 11 | F10: =_xlfn.XLOOKUP($B10,'INTL Restaurant Count Detail'!$B:$B,'INTL Restaurant Count Detail'!G:G) -> 11 | G10: =_xlfn.XLOOKUP($B10,'INTL Restaurant Count Detail'!$B:$B,'INTL Restaurant Count Detail'!H:H) -> 10 | H10: =_xlfn.XLOOKUP($B10,'INTL Restaurant Count Detail'!$B:$B,'INTL Restaurant Count Detail'!I:I) -> 10 | I10: =_xlfn.XLOOKUP($B10,'INTL Restaurant Count Detail'!$B:$B,'INTL Restaurant Count Detail'!J:J) -> 11 | J10: =_xlfn.XLOOKUP($B10,'INTL Restaurant Count Detail'!$B:$B,'INTL Restaurant Count Detail'!K:K) -> 11 | K10: =_xlfn.XLOOKUP($B10,'INTL Restaurant Count Detail'!$B:$B,'INTL Restaurant Count Detail'!L:L) -> 12 | L10: =_xlfn.XLOOKUP($B10,'INTL Restaurant Count Detail'!$B:$B,'INTL Restaurant Count Detail'!M:M) -> 12 | N10: =IFERROR(_xlfn.RRI(4,C10,G10),"-") -> -0.02354591 | O10: =IFERROR(_xlfn.RRI(5,G10,L10),"-") -> 0.037137289
B11: Myanmar | C11: =_xlfn.XLOOKUP($B11,'INTL Restaurant Count Detail'!$B:$B,'INTL Restaurant Count Detail'!D:D) -> 6 | D11: =_xlfn.XLOOKUP($B11,'INTL Restaurant Count Detail'!$B:$B,'INTL Restaurant Count Detail'!E:E) -> 7 | E11: =_xlfn.XLOOKUP($B11,'INTL Restaurant Count Detail'!$B:$B,'INTL Restaurant Count Detail'!F:F) -> 7 | F11: =_xlfn.XLOOKUP($B11,'INTL Restaurant Count Detail'!$B:$B,'INTL Restaurant Count Detail'!G:G) -> 7 | G11: =_xlfn.XLOOKUP($B11,'INTL Restaurant Count Detail'!$B:$B,'INTL Restaurant Count Detail'!H:H) -> 10 | H11: =_xlfn.XLOOKUP($B11,'INTL Restaurant Count Detail'!$B:$B,'INTL Restaurant Count Detail'!I:I) -> 10 | I11: =_xlfn.XLOOKUP($B11,'INTL Restaurant Count Detail'!$B:$B,'INTL Restaurant Count Detail'!J:J) -> 10 | J11: =_xlfn.XLOOKUP($B11,'INTL Restaurant Count Detail'!$B:$B,'INTL Restaurant Count Detail'!K:K) -> 11 | K11: =_xlfn.XLOOKUP($B11,'INTL Restaurant Count Detail'!$B:$B,'INTL Restaurant Count Detail'!L:L) -> 12 | L11: =_xlfn.XLOOKUP($B11,'INTL Restaurant Count Detail'!$B:$B,'INTL Restaurant Count Detail'!M:M) -> 13 | N11: =IFERROR(_xlfn.RRI(4,C11,G11),"-") -> 0.13621937 | O11: =IFERROR(_xlfn.RRI(5,G11,L11),"-") -> 0.053873952
B12: Taiwan | C12: =_xlfn.XLOOKUP($B12,'INTL Restaurant Count Detail'!$B:$B,'INTL Restaurant Count Detail'!D:D) -> 0 | D12: =_xlfn.XLOOKUP($B12,'INTL Restaurant Count Detail'!$B:$B,'INTL Restaurant Count Detail'!E:E) -> 0 | E12: =_xlfn.XLOOKUP($B12,'INTL Restaurant Count Detail'!$B:$B,'INTL Restaurant Count Detail'!F:F) -> 0 | F12: =_xlfn.XLOOKUP($B12,'INTL Restaurant Count Detail'!$B:$B,'INTL Restaurant Count Detail'!G:G) -> 3 | G12: =_xlfn.XLOOKUP($B12,'INTL Restaurant Count Detail'!$B:$B,'INTL Restaurant Count Detail'!H:H) -> 6 | H12: =_xlfn.XLOOKUP($B12,'INTL Restaurant Count Detail'!$B:$B,'INTL Restaurant Count Detail'!I:I) -> 9 | I12: =_xlfn.XLOOKUP($B12,'INTL Restaurant Count Detail'!$B:$B,'INTL Restaurant Count Detail'!J:J) -> 12 | J12: =_xlfn.XLOOKUP($B12,'INTL Restaurant Count Detail'!$B:$B,'INTL Restaurant Count Detail'!K:K) -> 15 | K12: =_xlfn.XLOOKUP($B12,'INTL Restaurant Count Detail'!$B:$B,'INTL Restaurant Count Detail'!L:L) -> 15 | L12: =_xlfn.XLOOKUP($B12,'INTL Restaurant Count Detail'!$B:$B,'INTL Restaurant Count Detail'!M:M) -> 15 | N12: =IFERROR(_xlfn.RRI(4,C12,G12),"-") -> - | O12: =IFERROR(_xlfn.RRI(5,G12,L12),"-") -> 0.20112443
B13: Laos | C13: =_xlfn.XLOOKUP($B13,'INTL Restaurant Count Detail'!$B:$B,'INTL Restaurant Count Detail'!D:D) -> 0 | D13: =_xlfn.XLOOKUP($B13,'INTL Restaurant Count Detail'!$B:$B,'INTL Restaurant Count Detail'!E:E) -> 0 | E13: =_xlfn.XLOOKUP($B13,'INTL Restaurant Count Detail'!$B:$B,'INTL Restaurant Count Detail'!F:F) -> 0 | F13: =_xlfn.XLOOKUP($B13,'INTL Restaurant Count Detail'!$B:$B,'INTL Restaurant Count Detail'!G:G) -> 2 | G13: =_xlfn.XLOOKUP($B13,'INTL Restaurant Count Detail'!$B:$B,'INTL Restaurant Count Detail'!H:H) -> 4 | H13: =_xlfn.XLOOKUP($B13,'INTL Restaurant Count Detail'!$B:$B,'INTL Restaurant Count Detail'!I:I) -> 7 | I13: =_xlfn.XLOOKUP($B13,'INTL Restaurant Count Detail'!$B:$B,'INTL Restaurant Count Detail'!J:J) -> 10 | J13: =_xlfn.XLOOKUP($B13,'INTL Restaurant Count Detail'!$B:$B,'INTL Restaurant Count Detail'!K:K) -> 13 | K13: =_xlfn.XLOOKUP($B13,'INTL Restaurant Count Detail'!$B:$B,'INTL Restaurant Count Detail'!L:L) -> 16 | L13: =_xlfn.XLOOKUP($B13,'INTL Restaurant Count Detail'!$B:$B,'INTL Restaurant Count Detail'!M:M) -> 19 | N13: =IFERROR(_xlfn.RRI(4,C13,G13),"-") -> - | O13: =IFERROR(_xlfn.RRI(5,G13,L13),"-") -> 0.36564784
B14: Singapore | C14: =_xlfn.XLOOKUP($B14,'INTL Restaurant Count Detail'!$B:$B,'INTL Restaurant Count Detail'!D:D) -> 5 | D14: =_xlfn.XLOOKUP($B14,'INTL Restaurant Count Detail'!$B:$B,'INTL Restaurant Count Detail'!E:E) -> 5 | E14: =_xlfn.XLOOKUP($B14,'INTL Restaurant Count Detail'!$B:$B,'INTL Restaurant Count Detail'!F:F) -> 4 | F14: =_xlfn.XLOOKUP($B14,'INTL Restaurant Count Detail'!$B:$B,'INTL Restaurant Count Detail'!G:G) -> 0 | G14: =_xlfn.XLOOKUP($B14,'INTL Restaurant Count Detail'!$B:$B,'INTL Restaurant Count Detail'!H:H) -> 0 | H14: =_xlfn.XLOOKUP($B14,'INTL Restaurant Count Detail'!$B:$B,'INTL Restaurant Count Detail'!I:I) -> 0 | I14: =_xlfn.XLOOKUP($B14,'INTL Restaurant Count Detail'!$B:$B,'INTL Restaurant Count Detail'!J:J) -> 0 | J14: =_xlfn.XLOOKUP($B14,'INTL Restaurant Count Detail'!$B:$B,'INTL Restaurant Count Detail'!K:K) -> 0 | K14: =_xlfn.XLOOKUP($B14,'INTL Restaurant Count Detail'!$B:$B,'INTL Restaurant Count Detail'!L:L) -> 0 | L14: =_xlfn.XLOOKUP($B14,'INTL Restaurant Count Detail'!$B:$B,'INTL Restaurant Count Detail'!M:M) -> 0 | N14: =IFERROR(_xlfn.RRI(4,C14,G14),"-") -> -1 | O14: =IFERROR(_xlfn.RRI(5,G14,L14),"-") -> 0
B15: Australia | C15: =_xlfn.XLOOKUP($B15,'INTL Restaurant Count Detail'!$B:$B,'INTL Restaurant Count Detail'!D:D) -> 1 | D15: =_xlfn.XLOOKUP($B15,'INTL Restaurant Count Detail'!$B:$B,'INTL Restaurant Count Detail'!E:E) -> 2 | E15: =_xlfn.XLOOKUP($B15,'INTL Restaurant Count Detail'!$B:$B,'INTL Restaurant Count Detail'!F:F) -> 0 | F15: =_xlfn.XLOOKUP($B15,'INTL Restaurant Count Detail'!$B:$B,'INTL Restaurant Count Detail'!G:G) -> 0 | G15: =_xlfn.XLOOKUP($B15,'INTL Restaurant Count Detail'!$B:$B,'INTL Restaurant Count Detail'!H:H) -> 0 | H15: =_xlfn.XLOOKUP($B15,'INTL Restaurant Count Detail'!$B:$B,'INTL Restaurant Count Detail'!I:I) -> 0 | I15: =_xlfn.XLOOKUP($B15,'INTL Restaurant Count Detail'!$B:$B,'INTL Restaurant Count Detail'!J:J) -> 0 | J15: =_xlfn.XLOOKUP($B15,'INTL Restaurant Count Detail'!$B:$B,'INTL Restaurant Count Detail'!K:K) -> 0 | K15: =_xlfn.XLOOKUP($B15,'INTL Restaurant Count Detail'!$B:$B,'INTL Restaurant Count Detail'!L:L) -> 0 | L15: =_xlfn.XLOOKUP($B15,'INTL Restaurant Count Detail'!$B:$B,'INTL Restaurant Count Detail'!M:M) -> 0 | N15: =IFERROR(_xlfn.RRI(4,C15,G15),"-") -> -1 | O15: =IFERROR(_xlfn.RRI(5,G15,L15),"-") -> 0
