Workbook
Name IQ_CH: 110000
Name IQ_CQ: 5000
Name IQ_CY: 10000
Name IQ_DAILY: 500000
Name IQ_FH: 100000
Name IQ_FQ: 500
Name IQ_FY: 1000
Name IQ_LTM: 2000
Name IQ_MONTH: 15000
Name IQ_NTM: 6000
Name IQ_WEEK: 50000
Name IQ_YTD: 3000
Name mkmkmkmkmk: #REF!
Name mshare: #REF!
Name ohfswhif: #REF!

Sheet Summary
C3: 2022 | D3: 2023 | E3: 2024 | F3: 2025 | G3: 2026 Plan
B4: Working | C4: =-'Marketing Fund 2022'!T108 -> 990072.61 | D4: =-'Marketing Fund 2023'!T108 -> 1572569.3 | E4: =-'Marketing Fund 2024'!T108 -> 1512356.1 | F4: =-'Marketing Fund 2025'!T107 -> 3285202 | G4: =-'Marketing Fund 2026 Plan'!T108 -> 3846000
B5: Non-working | C5: =-'Marketing Fund 2022'!T109 -> 1373816.3 | D5: =-'Marketing Fund 2023'!T109 -> 1611095.5 | E5: =-'Marketing Fund 2024'!T109 -> 2111103.9 | F5: =-'Marketing Fund 2025'!T108 -> 1709340.5 | G5: =-'Marketing Fund 2026 Plan'!T109 -> 2360141
B6: Total Marketing Spending | C6: =C4+C5 -> 2363888.9 | D6: =D4+D5 -> 3183664.8 | E6: =E4+E5 -> 3623459.9 | F6: =F4+F5 -> 4994542.5 | G6: =G4+G5 -> 6206141
B9: 3rd Party Delivery in Working | C9: =-'Marketing Fund 2022'!T111 -> 230660.5 | D9: =-'Marketing Fund 2023'!T111 -> 212987.02 | E9: =-'Marketing Fund 2024'!T111 -> 396833.13 | F9: =-'Marketing Fund 2025'!T110 -> 1241694.1 | G9: =-'Marketing Fund 2026 Plan'!T111 -> 1494000
B13: [Working examples]
B14: 3rd Party Delivery Media
B15: Paid Search
B16: Paid Social
B17: Online Video/Display
B18: NRO/Local Media
B19: Influencer/Content Prod
B20: Bonchon.com/App Promo
B21: EzCater Media

Sheet Marketing Fund 2022
B2: G/L Account | C2: Vendor in SAP | D2: Description | E2: Memo | F2: 3PD | H2: Actual
H3: F22P01 | I3: F22P02 | J3: F22P03 | K3: F22P04 | L3: F22P05 | M3: F22P06 | N3: F22P07 | O3: F22P08 | P3: F22P09 | Q3: F22P10 | R3: F22P11 | S3: F22P12 | T3: F22FY
B4: 4112211 Marketing Fee Incomes | H4: 155849.88 | I4: 150573.56 | J4: 158146.31 | K4: 159719.32 | L4: 161044.4 | M4: 154535.52 | N4: 169977.35 | O4: 164736.46 | P4: 240426.27 | Q4: 246885.45 | R4: 228289.87 | S4: 261922.63 | T4: =SUM(H4:S4) -> 2252107
B5: 4112212 Marketing fee incomes- Pepsi | H5: 0 | I5: 0 | J5: 0 | K5: 0 | L5: 0 | M5: 0 | N5: 0 | O5: 0 | P5: 0 | Q5: 0 | R5: 0 | S5: 0 | T5: =SUM(H5:S5) -> 0
B6: 4112213 Marketing fee incomes- Others | H6: 0 | I6: 0 | J6: 0 | K6: 0 | L6: 0 | M6: 0 | N6: 58.41 | O6: 60.57 | P6: 49.23 | Q6: 61.67 | R6: 3180.22 | S6: 554.01 | T6: =SUM(H6:S6) -> 3964.11
B7: Total Marketing income | H7: =SUM(H4:H6) -> 155849.88 | I7: =SUM(I4:I6) -> 150573.56 | J7: =SUM(J4:J6) -> 158146.31 | K7: =SUM(K4:K6) -> 159719.32 | L7: =SUM(L4:L6) -> 161044.4 | M7: =SUM(M4:M6) -> 154535.52 | N7: =SUM(N4:N6) -> 170035.76 | O7: =SUM(O4:O6) -> 164797.03 | ... T7: =SUM(T4:T6) -> 2256071.1
B9: (M)Agency | C9: Mindstream Media Group,LLC | H9: 0 | I9: -4000 | J9: -4000 | K9: -4000 | L9: -4000 | M9: -4000 | N9: -4000 | O9: -4000 | P9: -4000 | Q9: -4000 | R9: -4000 | S9: -4000 | T9: =SUM(H9:S9) -> -44000
B10: (M)Agency | C10: Propaganda, Inc. | H10: 0 | I10: -10000 | J10: -10000 | K10: -10000 | L10: -10000 | M10: -10000 | N10: -10000 | O10: -10000 | P10: -10000 | Q10: -10000 | R10: -10000 | S10: -10000 | T10: =SUM(H10:S10) -> -110000
B11: (M)Market research | C11: Propaganda, Inc. | H11: 0 | I11: 0 | J11: -1530 | K11: 0 | L11: 0 | M11: 0 | N11: 0 | O11: 0 | P11: 0 | Q11: 0 | R11: 0 | S11: 0 | T11: =SUM(H11:S11) -> -1530
B12: (M)Market research | C12: Strop Insights | H12: 0 | I12: -15500 | J12: -15500 | K12: 0 | L12: 0 | M12: 0 | N12: 0 | O12: 0 | P12: 0 | Q12: 0 | R12: 0 | S12: 0 | T12: =SUM(H12:S12) -> -31000
B13: (M)Menu | C13: The printing center, Inc | H13: -1101.61 | I13: -547.52 | J13: -559.36 | K13: -389.26 | L13: -23523.86 | M13: -3226.04 | N13: -7548.66 | O13: -1293.85 | P13: -3472.58 | Q13: -797.29 | R13: -677.99 | S13: -809.07 | T13: =SUM(H13:S13) -> -43947.09
B14: (M)Brand Development | C14: The printing center, Inc | H14: 0 | I14: -634.14 | J14: 0 | K14: 0 | L14: 0 | M14: 0 | N14: 0 | O14: 0 | P14: 0 | Q14: 0 | R14: 0 | S14: 0 | T14: =SUM(H14:S14) -> -634.14
B15: (M)Brand Development | C15: Magna Marketing LLC | H15: 0 | I15: 0 | J15: 0 | K15: -13833.34 | L15: -13833.34 | M15: -13833.34 | N15: 0 | O15: -13833.34 | P15: -13833.33 | Q15: 0 | R15: 0 | S15: 0 | T15: =SUM(H15:S15) -> -69166.69
B16: (M)Brand Development | C16: Salesforce.com, Inc. | H16: 0 | I16: 0 | J16: -13412.88 | K16: -13412.88 | L16: -13412.88 | M16: -13412.88 | N16: -27246.21 | O16: -13412.88 | P16: -13412.88 | Q16: -15648.36 | R16: -15648.36 | S16: -15648.36 | T16: =SUM(H16:S16) -> -154668.57
B17: (M)Brand Development | C17: Local Store Identity Field Day | H17: -6500 | I17: -6500 | J17: 0 | K17: 0 | L17: 0 | M17: 0 | N17: 0 | O17: 0 | P17: 0 | Q17: 0 | R17: 0 | S17: 0 | T17: =SUM(H17:S17) -> -13000
B18: (M)Brand Development | C18: Stingray Worldwide LLC | H18: 0 | I18: -87.3 | J18: 0 | K18: 0 | L18: 0 | M18: 0 | N18: 0 | O18: 0 | P18: 0 | Q18: 0 | R18: 0 | S18: 0 | T18: =SUM(H18:S18) -> -87.3
B19: (M)Menu Development | C19: Hyde Park Group, LLC | H19: 0 | I19: 0 | J19: 0 | K19: 0 | L19: 0 | M19: 0 | N19: 0 | O19: -54000 | P19: 0 | Q19: -54000 | R19: 0 | S19: 0 | T19: =SUM(H19:S19) -> -108000
B20: (M)Misc | C20: Bank of America | H20: 0 | I20: 0 | J20: -1 | K20: -5 | L20: -2 | M20: -1 | N20: -1 | O20: -2 | P20: -5 | Q20: 0 | R20: -2 | S20: -10 | T20: =SUM(H20:S20) -> -29
... B28: (M)Music | C28: Creative Media Solutions, LLC _Juke Boxy | H28: -780 | I28: -795 | J28: -795 | K28: -795 | L28: -840 | M28: -870 | N28: -900 | O28: -930 | P28: -990 | Q28: -1050 | R28: -2100 | S28: -1095 | T28: =SUM(H28:S28) -> -11940
B29: (M)National Advertisement | C29: Medium Giant Company, Inc Medium Giant | E29: Working | H29: 0 | I29: 0 | J29: 0 | K29: 0 | L29: 0 | M29: 0 | N29: 0 | O29: 0 | P29: 0 | Q29: 0 | R29: 0 | S29: -900 | T29: =SUM(H29:S29) -> -900
B30: (M)National Advertisement | C30: Valassis Direct Mail, Inc | E30: Working | H30: 0 | I30: 0 | J30: 0 | K30: 0 | L30: 0 | M30: 0 | N30: 0 | O30: 0 | P30: 0 | Q30: 0 | R30: 0 | S30: -4956.43 | T30: =SUM(H30:S30) -> -4956.43
B31: (M)Newsletter | C31: MailChimp | H31: -577.04 | I31: 577.04 | J31: 0 | K31: 0 | L31: 0 | M31: 0 | N31: 0 | O31: 0 | P31: 0 | Q31: 0 | R31: 0 | S31: 0 | T31: =SUM(H31:S31) -> 0
B32: (M)Others | C32: Blackbox Intelligence | H32: -1373.16 | I32: -1373.16 | J32: -1373.16 | K32: -1373.16 | L32: -1373.16 | M32: -1373.16 | N32: -1373.16 | O32: -1373.16 | P32: -1373.19 | Q32: -1382.19 | R32: -1492.69 | S32: -1492.69 | T32: =SUM(H32:S32) -> -16726.04
B33: (M)Others | C33: Mirus Information Tech Service, Inc | H33: -6374.18 | I33: 0 | J33: -7123.18 | K33: -14433.99 | L33: -7487.81 | M33: -7566.81 | N33: -7670 | O33: -8847.18 | P33: -8037.18 | Q33: -9657.18 | R33: -8680 | S33: -7915 | T33: =SUM(H33:S33) -> -93792.51
B34: (M)Others | C34: Bonchon Holdings LLC | H34: 0 | I34: 0 | J34: 0 | K34: 0 | L34: 0 | M34: 0 | N34: -8870.89 | O34: 0 | P34: 0 | Q34: 0 | R34: 0 | S34: 0 | T34: =SUM(H34:S34) -> -8870.89
B35: (M)Others | C35: The printing center, Inc | H35: -249.95 | I35: -254.79 | J35: -290.58 | K35: 0 | L35: -358.52 | M35: 0 | N35: 0 | O35: 0 | P35: 0 | Q35: 0 | R35: -302.5 | S35: 0 | T35: =SUM(H35:S35) -> -1456.34
B36: (M)Others | C36: Survey Monkey | H36: 0 | I36: 0 | J36: 0 | K36: 0 | L36: 0 | M36: 0 | N36: 0 | O36: 0 | P36: -418.08 | Q36: 0 | R36: 0 | S36: 0 | T36: =SUM(H36:S36) -> -418.08
B37: (M)Others | C37: ADOBE | H37: 0 | I37: 0 | J37: 0 | K37: 0 | L37: 0 | M37: 57.69 | N37: 0 | O37: 0 | P37: 0 | Q37: 0 | R37: 0 | S37: 0 | T37: =SUM(H37:S37) -> 57.69
B38: (M)Others | C38: Klaviyo Inc. | H38: -1113.08 | I38: -1109.57 | J38: -1124.63 | K38: -1124.63 | L38: -1160.79 | M38: -1177.93 | N38: 0 | O38: -1177.93 | P38: -1364.48 | Q38: -1364.48 | R38: -1364.48 | S38: 0 | T38: =SUM(H38:S38) -> -12082
B39: (M)Others | C39: Displays2go | H39: -1071.38 | I39: 0 | J39: 0 | K39: 0 | L39: 0 | M39: 0 | N39: 0 | O39: 0 | P39: 0 | Q39: 0 | R39: 0 | S39: 0 | T39: =SUM(H39:S39) -> -1071.38
B40: (M)Others | C40: Bank Of America | H40: -6 | I40: -3 | J40: -6 | K40: -2 | L40: 0 | M40: -10 | N40: 0 | O40: 0 | P40: 0 | Q40: 0 | R40: 0 | S40: 0 | T40: =SUM(H40:S40) -> -27
B41: (M)Others | C41: Printmoz.com | H41: 0 | I41: -49.38 | J41: -79 | K41: -32.73 | L41: -190.24 | M41: -110.33 | N41: 0 | O41: -149.16 | P41: 0 | Q41: 0 | R41: 0 | S41: -165.36 | T41: =SUM(H41:S41) -> -776.2
B42: (M)Others | C42: Etsy.com | H42: 0 | I42: 0 | J42: 0 | K42: -7.85 | L42: 0 | M42: 0 | N42: 0 | O42: 0 | P42: 0 | Q42: 0 | R42: 0 | S42: 0 | T42: =SUM(H42:S42) -> -7.85
... B52: (M)Photo & Video | C52: The Food Photo Agency, Inc. | H52: 0 | I52: 0 | J52: 0 | K52: 0 | L52: 0 | M52: -7972.57 | N52: 0 | O52: 0 | P52: 0 | Q52: 0 | R52: 0 | S52: 0 | T52: =SUM(H52:S52) -> -7972.57
B53: (M)Promotions | C53: Doordash, Inc | E53: Working | F53: 3rd Party Delivery | H53: 0 | I53: 0 | J53: -166813.5 | K53: 0 | L53: 0 | M53: 0 | N53: -37506 | O53: -26341 | P53: 0 | Q53: 0 | R53: 0 | S53: 0 | T53: =SUM(H53:S53) -> -230660.5
B54: (M)Promotions | C54: The printing center, Inc | H54: -21523.87 | I54: -503.42 | J54: -2613.69 | K54: -180.02 | L54: 0 | M54: 0 | N54: -10130.27 | O54: -13228.75 | P54: -223.21 | Q54: -324.4 | R54: -14816.1 | S54: 0 | T54: =SUM(H54:S54) -> -63543.73
B55: (M)Promotions | C55: Stingray Worldwide LLC | H55: 0 | I55: 0 | J55: -1474.91 | K55: 0 | L55: 0 | M55: 0 | N55: -933.03 | O55: 0 | P55: 0 | Q55: 0 | R55: 0 | S55: 0 | T55: =SUM(H55:S55) -> -2407.94
B56: (M)Promotions | C56: Bonchon.com | H56: 0 | I56: -300 | J56: 0 | K56: 0 | L56: 0 | M56: 0 | N56: 0 | O56: 0 | P56: 0 | Q56: 0 | R56: 0 | S56: 0 | T56: =SUM(H56:S56) -> -300
B57: (M)Promotions | C57: Cumulus Media Inc. | E57: Working | H57: 0 | I57: 0 | J57: 0 | K57: 0 | L57: 0 | M57: -3075 | N57: 0 | O57: 0 | P57: 0 | Q57: 0 | R57: 0 | S57: 0 | T57: =SUM(H57:S57) -> -3075
B58: (M)Promotions | C58: CDXL LLC | H58: 0 | I58: 0 | J58: 0 | K58: 0 | L58: 0 | M58: 0 | N58: -15000 | O58: 0 | P58: 0 | Q58: 0 | R58: 0 | S58: 0 | T58: =SUM(H58:S58) -> -15000
...

Sheet Marketing Fund 2023
B2: G/L Account | C2: Vendor in SAP | D2: Description | E2: Memo | F2: 3PD | H2: Actual
H3: F23P01 | I3: F23P02 | J3: F23P03 | K3: F23P04 | L3: F23P05 | M3: F23P06 | N3: F23P07 | O3: F23P08 | P3: F23P09 | Q3: F23P10 | R3: F23P11 | S3: F23P12 | T3: F23FY
B4: 4112211 Marketing Fee Incomes | H4: 248329.28 | I4: 236326.01 | J4: 257519.36 | K4: 255502.1 | L4: 253027.04 | M4: 195352.25 | N4: 172611.77 | O4: 227060.19 | P4: 243837.32 | Q4: 242625.91 | R4: 236007.16 | S4: 272029.42 | T4: =SUM(H4:S4) -> 2840227.8
B5: 4112212 Marketing fee incomes- Pepsi | H5: 0 | I5: 0 | J5: 35000 | K5: 0 | L5: 0 | M5: 0 | N5: 0 | O5: 7000 | P5: 0 | Q5: 0 | R5: 29113.04 | S5: 0 | T5: =SUM(H5:S5) -> 71113.04
B6: 4112213 Marketing fee incomes- Others | H6: 213.08 | I6: 265.57 | J6: 2082.62 | K6: 486.59 | L6: 740.13 | M6: 1519.62 | N6: 17.41 | O6: 95.97 | P6: 451.91 | Q6: 40.66 | R6: 5590.78 | S6: 0 | T6: =SUM(H6:S6) -> 11504.34
B7: Total Marketing income | H7: =SUM(H4:H6) -> 248542.36 | I7: =SUM(I4:I6) -> 236591.58 | J7: =SUM(J4:J6) -> 294601.98 | K7: =SUM(K4:K6) -> 255988.69 | L7: =SUM(L4:L6) -> 253767.17 | M7: =SUM(M4:M6) -> 196871.87 | N7: =SUM(N4:N6) -> 172629.18 | O7: =SUM(O4:O6) -> 234156.16 | ... T7: =SUM(T4:T6) -> 2922845.2
B9: (M)Agency | C9: Mindstream Media Group,LLC | D9: Retainer | H9: -4000 | I9: -4000 | J9: -4000 | K9: -4000 | L9: -4000 | M9: -4000 | N9: -4000 | O9: -4000 | P9: -4000 | Q9: -4000 | R9: -4000 | S9: -4000 | T9: =SUM(H9:S9) -> -48000
B10: (M)Agency | C10: Propaganda, Inc. | H10: -10000 | I10: -10000 | J10: -10000 | K10: -10000 | L10: -10000 | M10: -10000 | N10: -10000 | O10: -10000 | P10: -10000 | Q10: -10000 | R10: -10000 | S10: -10000 | T10: =SUM(H10:S10) -> -120000
B11: (M)Agency | C11: SPM COMMUNICATIONS, INC | D11: SPM: B2C PR | H11: 0 | I11: -7955 | J11: -12570 | K11: -12570 | L11: -13984.96 | M11: -13225.5 | N11: -12570 | O11: -12570 | P11: -12570 | Q11: -13225.5 | R11: -12570 | S11: -12570 | T11: =SUM(H11:S11) -> -136380.96
B12: (M)CRM/Loyalty | C12: RAF Enterprises L.L.C. | D12: Richard Flores: Customer Database | H12: 0 | I12: 0 | J12: -10562 | K12: -1500 | L12: -2193.75 | M12: -1500 | N12: -1500 | O12: -1500 | P12: -1500 | Q12: -1500 | R12: -1500 | S12: -1500 | T12: =SUM(H12:S12) -> -24755.75
B13: (M)CRM/Loyalty | C13: Salesforce.com, Inc. | H13: -15648.36 | I13: -16317.32 | J13: -15648.36 | K13: -16171.55 | L13: -16544.08 | M13: -16171.55 | N13: -16171.55 | O13: -16171.55 | P13: -16171.55 | Q13: -16171.55 | R13: -16171.55 | S13: -16171.55 | T13: =SUM(H13:S13) -> -193530.52
B14: (M)Market research | C14: Propaganda, Inc. | H14: 0 | I14: 0 | J14: -1792 | K14: 0 | L14: 0 | M14: 0 | N14: 0 | O14: 0 | P14: 0 | Q14: 0 | R14: 0 | S14: 0 | T14: =SUM(H14:S14) -> -1792
B15: (M)Market research | C15: Strop Insights | H15: 0 | I15: 0 | J15: 0 | K15: -12500 | L15: 0 | M15: 0 | N15: 0 | O15: 0 | P15: 0 | Q15: 0 | R15: 0 | S15: 0 | T15: =SUM(H15:S15) -> -12500
B16: (M)Menu | C16: The printing center, Inc | D16: Menu Printing: Print Center | H16: -503.04 | I16: -750.62 | J16: 0 | K16: -797.56 | L16: 0 | M16: 0 | N16: 0 | O16: -4033.76 | P16: 0 | Q16: -12049.33 | R16: 0 | S16: 0 | T16: =SUM(H16:S16) -> -18134.31
B17: (M)Menu Development | C17: Remarkable Culinary LLC | H17: 0 | I17: 0 | J17: -5000 | K17: -20622.26 | L17: 0 | M17: -2500 | N17: 0 | O17: 0 | P17: 0 | Q17: 0 | R17: 0 | S17: 0 | T17: =SUM(H17:S17) -> -28122.26
B18: (M)Menu Development | C18: Jake's Inc. | H18: 0 | I18: 0 | J18: 0 | K18: -495.5 | L18: 0 | M18: 0 | N18: 0 | O18: 0 | P18: 0 | Q18: 0 | R18: 0 | S18: 0 | T18: =SUM(H18:S18) -> -495.5
B19: (M)Menu Development | C19: SPM COMMUNICATIONS, INC | H19: 0 | I19: 0 | J19: 0 | K19: -1058.74 | L19: 0 | M19: 0 | N19: 0 | O19: 0 | P19: 0 | Q19: 0 | R19: 0 | S19: 0 | T19: =SUM(H19:S19) -> -1058.74
B20: (M)Menu Development | C20: Stingray Worldwide LLC | H20: 0 | I20: 0 | J20: 0 | K20: -789.9 | L20: 0 | M20: 0 | N20: 0 | O20: 0 | P20: 0 | Q20: 0 | R20: 0 | S20: 0 | T20: =SUM(H20:S20) -> -789.9
B21: (M)Menu Development | C21: DOT IT RESTAURANT LLC | H21: 0 | I21: 0 | J21: 0 | K21: 0 | L21: 0 | M21: -1092.34 | N21: 0 | O21: 0 | P21: 0 | Q21: 0 | R21: 0 | S21: 0 | T21: =SUM(H21:S21) -> -1092.34
B22: (M)Menu Development | C22: Impact Brands LLC | H22: 0 | I22: 0 | J22: 0 | K22: 0 | L22: 0 | M22: 0 | N22: 0 | O22: 0 | P22: 0 | Q22: 0 | R22: -5000 | S22: 0 | T22: =SUM(H22:S22) -> -5000
B23: (M)Misc | C23: Bank of America | H23: -5 | I23: -2 | J23: -7 | K23: -5 | L23: -14 | M23: -2 | N23: -26 | O23: -4 | P23: -4 | Q23: -14 | R23: -2 | S23: -3 | T23: =SUM(H23:S23) -> -88
B24: (M)Misc | C24: DOT IT RESTAURANT LLC | D24: Flavor Stickers | H24: 0 | I24: 0 | J24: 0 | K24: 0 | L24: 0 | M24: 0 | N24: 0 | O24: 0 | P24: 0 | Q24: 9.094947e-13 | R24: 0 | S24: -3851.35 | T24: =SUM(H24:S24) -> -3851.35
B25: (M)Misc | C25: Stingray Worldwide LLC | H25: 0 | I25: 0 | J25: 0 | K25: 0 | L25: 0 | M25: 0 | N25: 0 | O25: -147.76 | P25: 0 | Q25: 0 | R25: 0 | S25: 0 | T25: =SUM(H25:S25) -> -147.76
B26: (M)Misc | C26: Ferraro Foods | H26: 0 | I26: 0 | J26: -2525.27 | K26: 0 | L26: 0 | M26: 0 | N26: 0 | O26: 0 | P26: 0 | Q26: 0 | R26: 0 | S26: 0 | T26: =SUM(H26:S26) -> -2525.27
B27: (M)Misc | C27: Displays2go | H27: 0 | I27: 0 | J27: -1135.36 | K27: 0 | L27: 0 | M27: 0 | N27: 0 | O27: 0 | P27: 0 | Q27: 0 | R27: 0 | S27: 0 | T27: =SUM(H27:S27) -> -1135.36
B28: (M)Misc | C28: Bonchon Holdings LLC | H28: 0 | I28: 0 | J28: 0 | K28: -725 | L28: 0 | M28: 0 | N28: -950 | O28: 0 | P28: 0 | Q28: -399.69 | R28: 0 | S28: 0 | T28: =SUM(H28:S28) -> -2074.69
B29: (M)Misc | C29: The printing center, Inc | H29: 0 | I29: -48.15 | J29: -27.09 | K29: 0 | L29: 0 | M29: -157.24 | N29: -27.98 | O29: -22.92 | P29: 0 | Q29: -27.71 | R29: -33.13 | S29: 0 | T29: =SUM(H29:S29) -> -344.22
B30: (M)Music | C30: Creative Media Solutions, LLC _Juke Boxy | H30: -1095 | I30: -1520 | J30: -1350 | K30: -1110 | L30: -1170 | M30: -1185 | N30: -1185 | O30: -1185 | P30: -1185 | Q30: -1200 | R30: -1230 | S30: -1245 | T30: =SUM(H30:S30) -> -14660
B31: (M)National Advertisement | C31: Medium Giant Company, Inc Medium Giant | E31: Working | H31: 0 | I31: -600 | J31: 0 | K31: 0 | L31: 0 | M31: 0 | N31: 0 | O31: 0 | P31: 0 | Q31: 0 | R31: -1307.24 | S31: 0 | T31: =SUM(H31:S31) -> -1907.24
B32: (M)National Advertisement | C32: Cardlytics, Inc. | E32: Working | H32: 0 | I32: 0 | J32: 0 | K32: 0 | L32: 0 | M32: 0 | N32: 0 | O32: 0 | P32: 0 | Q32: 0 | R32: -140041.08 | S32: -127783 | T32: =SUM(H32:S32) -> -267824.08
B33: (M)National Advertisement | C33: Intrinsic Digital, Inc. RestaurantGeofencing.com | E33: Working | H33: 0 | I33: 0 | J33: 0 | K33: -5950 | L33: -2380 | M33: 0 | N33: 0 | O33: 0 | P33: 0 | Q33: 0 | R33: 0 | S33: 0 | T33: =SUM(H33:S33) -> -8330
B34: (M)National Advertisement | C34: Mindstream Media Group,LLC | E34: Working | H34: -50718 | I34: -109722.55 | J34: -85010.77 | K34: -98279.5 | L34: -90639.7 | M34: -55870.8 | N34: -124772.25 | O34: -110154.75 | P34: -76392.01 | Q34: -59670 | R34: -59339.55 | S34: -46726.2 | T34: =SUM(H34:S34) -> -967296.08
B35: (M)Nutrition Fact | C35: Nutritional Information Services | H35: 0 | I35: 0 | J35: 0 | K35: -270 | L35: 0 | M35: -60 | N35: -40 | O35: 0 | P35: 0 | Q35: 0 | R35: 0 | S35: 0 | T35: =SUM(H35:S35) -> -370
B36: (M)Others | C36: Blackbox Intelligence | H36: -1492.69 | I36: -1492.69 | J36: -1492.69 | K36: -1492.69 | L36: -1492.69 | M36: -1492.69 | N36: -1492.69 | O36: -1492.69 | P36: -1492.69 | Q36: -1492.69 | R36: -843.12 | S36: -843.12 | T36: =SUM(H36:S36) -> -16613.14
B37: (M)Others | C37: Mirus Information Tech Service, Inc | H37: -9246 | I37: -9322 | J37: -9272 | K37: -9372 | L37: -9348 | M37: -9398 | N37: -9467.89 | O37: -9391.89 | P37: -9624.16 | Q37: -9626.16 | R37: -9702.16 | S37: -10054.16 | T37: =SUM(H37:S37) -> -113824.42
B38: (M)Others | C38: Pepsi | H38: 0 | I38: 0 | J38: 0 | K38: 0 | L38: 0 | M38: 0 | N38: 0 | O38: -7000 | P38: 0 | Q38: 0 | R38: -8000 | S38: -10554.72 | T38: =SUM(H38:S38) -> -25554.72
B39: (M)Others | C39: Bonchon Holdings LLC | H39: 0 | I39: -2064.06 | J39: -6809.98 | K39: -6542.45 | L39: -788.13 | M39: -2188.98 | N39: -51.69 | O39: -1088.47 | P39: -1091.34 | Q39: -146.46 | R39: -2959.27 | S39: -185.12 | T39: =SUM(H39:S39) -> -23915.95
B40: (M)Others | C40: The printing center, Inc | H40: 0 | I40: 2875.01 | J40: 0 | K40: 0 | L40: 0 | M40: 0 | N40: 0 | O40: 0 | P40: 0 | Q40: 0 | R40: 0 | S40: 0 | T40: =SUM(H40:S40) -> 2875.01
B41: (M)Others | C41: Sprout Social, Inc | H41: 0 | I41: -2875.01 | J41: 0 | K41: 0 | L41: 0 | M41: 0 | N41: 0 | O41: 0 | P41: 0 | Q41: 0 | R41: 0 | S41: 0 | T41: =SUM(H41:S41) -> -2875.01
B42: (M)Others | C42: DOT IT RESTAURANT LLC | H42: 0 | I42: 0 | J42: 0 | K42: 0 | L42: 0 | M42: 0 | N42: 0 | O42: 0 | P42: -7321.55 | Q42: -518.92 | R42: 0 | S42: 0 | T42: =SUM(H42:S42) -> -7840.47
...

Sheet Marketing Fund 2024
B2: G/L Account | C2: Vendor in SAP | D2: Description | E2: Memo | F2: 3PD | H2: Actual
H3: F24P01 | I3: F24P02 | J3: F24P03 | K3: F24P04 | L3: F24P05 | M3: F24P06 | N3: F24P07 | O3: F24P08 | P3: F24P09 | Q3: F24P10 | R3: F24P11 | S3: F24P12 | T3: FY
B4: 4112211 Marketing Fee Incomes | H4: 241787.94 | I4: 241505.22 | J4: 271092.7 | K4: 251170.52 | L4: 258720.68 | M4: 253006.19 | N4: 253904.2 | O4: 260617.5 | P4: 241591.01 | Q4: 248120.21 | R4: 242597.7 | S4: 265391.09 | T4: =SUM(H4:S4) -> 3029505
B5: 4112212 Marketing fee incomes- Pepsi | H5: 0 | I5: 7000 | J5: 2000 | K5: 23148 | L5: 0 | M5: 0 | N5: 11000 | O5: 6000 | P5: 0 | Q5: 48680.28 | R5: 0 | S5: 0 | T5: =SUM(H5:S5) -> 97828.28
B6: 4112213 Marketing fee incomes- Others | H6: 1062.8 | I6: 1378 | J6: 3933.37 | K6: 703 | L6: 2286.95 | M6: 1944 | N6: 1953.9 | O6: 1910.95 | P6: 0 | Q6: 0 | R6: 5674.51 | S6: 1696.2 | T6: =SUM(H6:S6) -> 22543.68
B7: Total Marketing income | H7: =SUM(H4:H6) -> 242850.74 | I7: =SUM(I4:I6) -> 249883.22 | J7: =SUM(J4:J6) -> 277026.07 | K7: =SUM(K4:K6) -> 275021.52 | L7: =SUM(L4:L6) -> 261007.63 | M7: =SUM(M4:M6) -> 254950.19 | N7: =SUM(N4:N6) -> 266858.1 | O7: =SUM(O4:O6) -> 268528.45 | ... S7: =SUM(S4:S6) -> 267087.29 | T7: =SUM(H7:S7) -> 3149876.9
B9: (M)Agency | C9: Mindstream Media Group,LLC | D9: MMG: Media Retainer | H9: -9750 | I9: -9750 | J9: -9750 | K9: -4875 | L9: 0 | M9: 0 | N9: 0 | O9: 0 | P9: 0 | Q9: 0 | R9: 0 | S9: 0 | T9: =SUM(H9:S9) -> -34125
B10: (M)Agency | C10: CossmanPR LLC | D10: Crossman: B2C PR Monthly | H10: 0 | I10: -6000 | J10: -6000 | K10: -6433.33 | L10: -6433.33 | M10: -6433.34 | N10: -6250 | O10: -6250 | P10: -6250 | Q10: -6216.67 | R10: -6216.67 | S10: -6216.66 | T10: =SUM(H10:S10) -> -68700
B11: (M)Agency | C11: Propaganda, Inc. | D11: Creative Agency Propoganda: (ends in May 17) | H11: -10000 | I11: -10000 | J11: -10000 | K11: -10000 | L11: -5667 | M11: 0 | N11: 0 | O11: 0 | P11: 0 | Q11: 0 | R11: 0 | S11: 0 | T11: =SUM(H11:S11) -> -45667
B12: (M)Agency | C12: CarsonDoyle Creative Agency,Ltd. | D12: Creeative Retainer: Carson & Doyle | H12: 0 | I12: 0 | J12: 0 | K12: 0 | L12: 0 | M12: 0 | N12: -19145 | O12: -35725 | P12: -15000 | Q12: -17900 | R12: -15000 | S12: -15000 | T12: =SUM(H12:S12) -> -117770
B13: (M)Agency | D13: Creative, out of scope | H13: 0 | I13: 0 | J13: 0 | K13: -5700 | L13: 0 | M13: -1200 | N13: 0 | O13: 0 | P13: 0 | Q13: 0 | R13: 0 | S13: 0 | T13: =SUM(H13:S13) -> -6900
B14: (M)Agency | C14: Calise Partners, LLC Imaginuity | D14: Imaginuity: SEO Set Up | H14: 0 | I14: 0 | J14: 0 | K14: 0 | L14: -10009.74 | M14: 0 | N14: 0 | O14: 0 | P14: 0 | Q14: 0 | R14: 0 | S14: 0 | T14: =SUM(H14:S14) -> -10009.74
B15: (M)Agency | C15: Calise Partners, LLC Imaginuity | D15: Imaginuity: Site Optimization MGMT | H15: 0 | I15: 0 | J15: 0 | K15: 0 | L15: 0 | M15: 0 | N15: 0 | O15: -2457.13 | P15: -2457.13 | Q15: -2457.13 | R15: -2457.13 | S15: -2457.13 | T15: =SUM(H15:S15) -> -12285.65
B16: (M)Agency | C16: Wasserman Media Group, LLC | D16: MMG: Media Retainer 1 | H16: 0 | I16: 0 | J16: -10500 | K16: 0 | L16: 0 | M16: 0 | N16: 0 | O16: 0 | P16: 0 | Q16: 0 | R16: 0 | S16: 0 | T16: =SUM(H16:S16) -> -10500
B17: (M)Agency | C17: SPM COMMUNICATIONS, INC | D17: SPM: B2C PR | H17: -12570 | I17: -17304.6 | J17: 0 | K17: 0 | L17: 0 | M17: 0 | N17: 0 | O17: 0 | P17: 0 | Q17: 0 | R17: 0 | S17: 0 | T17: =SUM(H17:S17) -> -29874.6
B18: (M)CRM/Loyalty | C18: RAF Enterprises L.L.C. | D18: Richard Flores: Customer Database | H18: -1500 | I18: -1500 | J18: -1500 | K18: -1500 | L18: -1500 | M18: -1500 | N18: -1500 | O18: -1500 | P18: -1500 | Q18: -1500 | R18: -1500 | S18: -1500 | T18: =SUM(H18:S18) -> -18000
B19: (M)CRM/Loyalty | C19: Salesforce.com, Inc. | D19: Salesforce: Cost Per Month | H19: -16171.52 | I19: -16171.52 | J19: -16171.67 | K19: -16171.55 | L19: -16171.55 | M19: -16171.55 | N19: -16171.55 | O19: -16171.55 | P19: -16171.52 | Q19: -16171.55 | R19: -16171.55 | S19: -16171.55 | T19: =SUM(H19:S19) -> -194058.63
B20: (M)Market research | C20: Survey Monkey | D20: Survey Monkey Subscription | H20: 0 | I20: 0 | J20: 0 | K20: 0 | L20: 0 | M20: 0 | N20: 0 | O20: 0 | P20: -509.54 | Q20: 0 | R20: 0 | S20: 0 | T20: =SUM(H20:S20) -> -509.54
B21: (M)Market research | C21: GetTattle Inc | D21: Tattle: Guest Sat Program Pilot Test | H21: 0 | I21: 0 | J21: 0 | K21: -1250 | L21: 0 | M21: -1250 | N21: -1250 | O21: 0 | P21: 0 | Q21: 0 | R21: 0 | S21: -14700 | T21: =SUM(H21:S21) -> -18450
B22: (M)Market research | C22: GetTattle Inc | D22: Tattle: Guest Sat System Rollout | H22: 0 | I22: 0 | J22: 0 | K22: 0 | L22: 0 | M22: 0 | N22: -7050 | O22: 0 | P22: -7050 | Q22: -7050 | R22: -7050 | S22: 0 | T22: =SUM(H22:S22) -> -28200
B23: (M)Market research | C23: Cassandra Cornell, LLC | D23: Meda Spend, Restaurant Profiles, Trailblazer (all LSM) | H23: 0 | I23: 0 | J23: 0 | K23: 0 | L23: -2500 | M23: -3000 | N23: -5625 | O23: 0 | P23: 0 | Q23: 0 | R23: 0 | S23: -3500 | T23: =SUM(H23:S23) -> -14625
B24: (M)Market research | C24: U30 Group, Inc. | D24: Ethnography | H24: 0 | I24: -36200 | J24: 0 | K24: -38758.76 | L24: 0 | M24: 0 | N24: 0 | O24: 0 | P24: 0 | Q24: 0 | R24: 0 | S24: 0 | T24: =SUM(H24:S24) -> -74958.76
B25: (M)Menu | C25: The printing center, Inc | D25: Menu Printing: Print Center | H25: -1294.25 | I25: -12172.87 | J25: -535.1 | K25: -11528.6 | L25: 0 | M25: 0 | N25: -15136.31 | O25: 0 | P25: 0 | Q25: 0 | R25: 0 | S25: 0 | T25: =SUM(H25:S25) -> -40667.13
... B41: (M)National Advertisement | C41: Wasserman Media Group, LLC | D41: Amplification Media | H41: 0 | I41: 0 | J41: -70000 | K41: 0 | L41: 0 | M41: 0 | N41: 0 | O41: 0 | P41: 0 | Q41: 0 | R41: 0 | S41: 0 | T41: =SUM(H41:S41) -> -70000
B42: (M)National Advertisement | C42: Medium Giant Company, Inc Medium Giant | D42: Medium Giant Company, Inc Medium Giant | E42: Working | H42: 0 | I42: 0 | J42: -2225.76 | K42: 0 | L42: 0 | M42: 0 | N42: 0 | O42: 0 | P42: 0 | Q42: 0 | R42: 0 | S42: 0 | T42: =SUM(H42:S42) -> -2225.76
B43: (M)National Advertisement | C43: Marden-Kane Inc | D43: Local Activation/Influencer/Social Content 1 | E43: Working | H43: 0 | I43: 0 | J43: -4548 | K43: 0 | L43: 0 | M43: 0 | N43: 0 | O43: 0 | P43: 0 | Q43: 0 | R43: 0 | S43: 0 | T43: =SUM(H43:S43) -> -4548
B44: (M)National Advertisement | C44: Wasserman Media Group, LLC | D44: Local Activation/Influencer/Social Content | E44: Working | H44: 0 | I44: 0 | J44: -20000 | K44: 0 | L44: -20000 | M44: 0 | N44: 0 | O44: 0 | P44: 0 | Q44: 0 | R44: 0 | S44: 0 | T44: =SUM(H44:S44) -> -40000
B45: (M)National Advertisement | C45: CossmanPR LLC | D45: Local Activation/Influencer/Social Content 2 | E45: Working | H45: 0 | I45: 0 | J45: 0 | K45: 0 | L45: 0 | M45: 0 | N45: -7000 | O45: 0 | P45: -7000 | Q45: 0 | R45: 4940.46 | S45: 0 | T45: =SUM(H45:S45) -> -9059.54
B46: (M)National Advertisement | C46: D. Augustine & Associates Augustine Agency | D46: D. Augustine & Associates Augustine Agency | E46: Working | H46: 0 | I46: -12616 | J46: 0 | K46: 0 | L46: -20475 | M46: 0 | N46: 0 | O46: 0 | P46: 0 | Q46: 0 | R46: 0 | S46: 0 | T46: =SUM(H46:S46) -> -33091
B47: (M)National Advertisement | C47: Calise Partners, LLC Imaginuity | D47: Media 1 | E47: Working | H47: 0 | I47: 0 | J47: 0 | K47: 0 | L47: -64000 | M47: -64000 | N47: -153987.82 | O47: -133177.8 | P47: -131096.9 | Q47: -153986.84 | R47: -25922.29 | S47: 0 | T47: =SUM(H47:S47) -> -726171.65
B48: (M)National Advertisement | C48: Mindstream Media Group,LLC | D48: Media | E48: Working | H48: -37617.97 | I48: -65941.37 | J48: -79356.73 | K48: -13303.98 | L48: 0 | M48: 0 | N48: 0 | O48: 0 | P48: 0 | Q48: 0 | R48: 0 | S48: 0 | T48: =SUM(H48:S48) -> -196220.05
B49: (M)Others | C49: Blackbox Intelligence | D49: Black Box: Industry Data | H49: -843.12 | I49: -843.12 | J49: -843.12 | K49: -843.12 | L49: -843.12 | M49: -843.12 | N49: -843.12 | O49: -843.12 | P49: -843.12 | Q49: -843.12 | R49: 0 | S49: 0 | T49: =SUM(H49:S49) -> -8431.2
B50: (M)Others | C50: Mirus Information Tech Service, Inc | D50: Mirus: Data Feed | H50: -9923.89 | I50: -10073.89 | J50: -10125.89 | K50: -10403.89 | L50: -10379.89 | M50: -10536 | N50: -10842 | O50: -11194 | P50: -10944 | Q50: -11196 | R50: -11172 | S50: -11298 | T50: =SUM(H50:S50) -> -128089.45
B51: (M)Others | C51: Pepsi | D51: Pepsi | H51: 0 | I51: -7000 | J51: -2000 | K51: -13074 | L51: 0 | M51: 0 | N51: -11000 | O51: -6000 | P51: 0 | Q51: -24340.14 | R51: 0 | S51: -0.02 | T51: =SUM(H51:S51) -> -63414.16
B52: (M)Others | C52: Bonchon Holdings LLC | D52: Brand Expenses (Reports) | H52: -1112.94 | I52: -2461.88 | J52: -8323.22 | K52: -4041.14 | L52: -225.89 | M52: -4463.32 | N52: -2292.18 | O52: -1558.73 | P52: -10531.24 | Q52: -954.98 | R52: -2648.31 | S52: -867.5 | T52: =SUM(H52:S52) -> -39481.33
B53: (M)Others | C53: Fedex | D53: Fedex | H53: 0 | I53: 0 | J53: 0 | K53: 0 | L53: -282.9 | M53: -1937.39 | N53: -192.72 | O53: 0 | P53: 0 | Q53: 0 | R53: 0 | S53: 0 | T53: =SUM(H53:S53) -> -2413.01
B54: (M)Others | C54: Stevenson Ranch CA | D54: Stevenson Ranch CA | H54: 0 | I54: 0 | J54: 0 | K54: 0 | L54: 0 | M54: 0 | N54: 0 | O54: 0 | P54: 0 | Q54: -5000 | R54: 0 | S54: 0 | T54: =SUM(H54:S54) -> -5000
B55: (M)Others | C55: COLORMARK, L.C. | D55: COLORMARK, L.C. | H55: 0 | I55: 0 | J55: 0 | K55: 0 | L55: 0 | M55: 0 | N55: 0 | O55: 0 | P55: 0 | Q55: 0 | R55: 0 | S55: -220 | T55: =SUM(H55:S55) -> -220
B56: (M)Overhead expense | C56: Overhead | D56: Team Salaries & Benefits | H56: -46135.76 | I56: -52316.55 | J56: -44001.09 | K56: -45371.28 | L56: -47294.11 | M56: -23346.68 | N56: -37010.74 | O56: -40316.01 | P56: -38247.92 | Q56: -41409.56 | R56: -38329.39 | S56: -41164.02 | T56: =SUM(H56:S56) -> -494943.11
B57: (M)Photo & Video | C57: Propaganda, Inc. | D57: Video Shoot & Editing DC | H57: 0 | I57: 0 | J57: -3840 | K57: 0 | L57: -1200 | M57: 0 | N57: 0 | O57: 0 | P57: 0 | Q57: 0 | R57: 0 | S57: 0 | T57: =SUM(H57:S57) -> -5040
...

Sheet Marketing Fund 2025
B2: G/L Account | C2: Vendor in SAP | D2: Description | E2: Memo | F2: 3PD | H2: Actual | V2: -1
H3: F25P01 | I3: F25P02 | J3: F25P03 | K3: F25P04 | L3: F25P05 | M3: F25P06 | N3: F25P07 | O3: F25P08 | P3: F25P09 | Q3: F25P10 | R3: F25P11 | S3: F25P12 | T3: FY
B4: 4112211 Marketing Fee Incomes | H4: 250044.62 | I4: 233033.91 | J4: 261841.98 | K4: 251985.57 | L4: 270270.3 | M4: 261691.28 | N4: 272963.39 | O4: 281699.74 | P4: 258868.17 | Q4: 272695.04 | R4: 268056.97 | S4: 284302.68 | T4: =SUM(H4:S4) -> 3167453.7
B5: 4112212 Marketing fee incomes- Pepsi | H5: 6000 | I5: 0 | J5: 0 | K5: 25116 | L5: 0 | M5: 3000 | N5: 0 | O5: 0 | P5: 4000 | Q5: 57682.77 | R5: 0 | S5: 0 | T5: =SUM(H5:S5) -> 95798.77
B6: 4112213 Marketing fee incomes- Others | H6: 0 | I6: 3709.81 | J6: 0 | K6: 17329.81 | L6: 3620.55 | M6: 0 | N6: 0 | O6: 0 | P6: 3493.31 | Q6: 0 | R6: 0 | S6: 0 | T6: =SUM(H6:S6) -> 28153.48
B7: Total Marketing income | H7: =SUM(H4:H6) -> 256044.62 | I7: =SUM(I4:I6) -> 236743.72 | J7: =SUM(J4:J6) -> 261841.98 | K7: =SUM(K4:K6) -> 294431.38 | L7: =SUM(L4:L6) -> 273890.85 | M7: =SUM(M4:M6) -> 264691.28 | N7: =SUM(N4:N6) -> 272963.39 | O7: =SUM(O4:O6) -> 281699.74 | ... S7: =SUM(S4:S6) -> 284302.68 | T7: =SUM(H7:S7) -> 3291405.9
B9: (M)Agency | C9: CarsonDoyle Creative Agency,Ltd. | D9: Retainer | H9: -19000 | I9: -24000 | J9: -26000 | K9: -26000 | L9: -26000 | M9: -26000 | N9: -26000 | O9: -26000 | P9: -26000 | Q9: -27800 | R9: -26000 | S9: -26000 | T9: =SUM(H9:S9) -> -304800
B10: (M)Agency | C10: COLORMARK, L.C. | H10: 0 | I10: 0 | J10: 0 | K10: 0 | L10: -3472.53 | M10: 0 | N10: 0 | O10: 0 | P10: 0 | Q10: 0 | R10: 0 | S10: 0 | T10: =SUM(H10:S10) -> -3472.53
B11: (M)Agency | C11: Brandverge, Inc. | H11: 0 | I11: 0 | J11: 0 | K11: 0 | L11: 0 | M11: -15600 | N11: 0 | O11: 0 | P11: 0 | Q11: 0 | R11: 0 | S11: 0 | T11: =SUM(H11:S11) -> -15600
B12: (M)Agency | C12: Calise Partners, LLC Imaginuity | H12: -2457.13 | I12: -2457.13 | J12: -2457.13 | K12: 0 | L12: 0 | M12: 0 | N12: 0 | O12: 0 | P12: 0 | Q12: 0 | R12: 0 | S12: 0 | T12: =SUM(H12:S12) -> -7371.39
B13: (M)Agency | C13: Veylan Inc | D13: AI Marketing Tool | H13: 0 | I13: 0 | J13: 0 | K13: 0 | L13: 0 | M13: 0 | N13: 0 | O13: 0 | P13: 0 | Q13: 0 | R13: -10000 | S13: -10000 | T13: =SUM(H13:S13) -> -20000
B14: (M)Agency | C14: CossmanPR LLC | H14: -6433.33 | I14: -6433.33 | J14: -6433.34 | K14: -6233 | L14: -6233 | M14: -6233 | N14: -6233 | O14: -6233 | P14: -6233 | Q14: -6000 | R14: -7584.17 | S14: -6000 | T14: =SUM(H14:S14) -> -76282.17
B15: (M)CRM/Loyalty | C15: RAF Enterprises L.L.C. | H15: -1500 | I15: -1500 | J15: -1500 | K15: -1500 | L15: 0 | M15: 0 | N15: 0 | O15: 0 | P15: 0 | Q15: 0 | R15: 0 | S15: 0 | T15: =SUM(H15:S15) -> -6000
B16: (M)CRM/Loyalty | C16: Salesforce.com | H16: -16171.55 | I16: -16171.55 | J16: -16171.53 | K16: 0 | L16: 0 | M16: 0 | N16: 0 | O16: 0 | P16: 0 | Q16: 0 | R16: 0 | S16: 0 | T16: =SUM(H16:S16) -> -48514.63
B17: (M)CRM/Loyalty | C17: Fishbowl Inc. | H17: 0 | I17: -2083.33 | J17: -2083.33 | K17: -2083.33 | L17: -2128.33 | M17: -2173.33 | N17: -2083.33 | O17: -2083.33 | P17: -2083.33 | Q17: -2083.33 | R17: -2083.33 | S17: -2083.33 | T17: =SUM(H17:S17) -> -23051.63
B18: (M)Market research | C18: Survey Monkey | H18: 0 | I18: 0 | J18: 0 | K18: 0 | L18: 0 | M18: 0 | N18: 0 | O18: 0 | P18: -509.54 | Q18: 0 | R18: 0 | S18: 0 | T18: =SUM(H18:S18) -> -509.54
B19: (M)Market research | C19: GetTattle Inc | D19: Tattle responses | H19: 0 | I19: 0 | J19: 0 | K19: 0 | L19: 0 | M19: 0 | N19: 0 | O19: 0 | P19: 0 | Q19: -1750 | R19: 0 | S19: 0 | T19: =SUM(H19:S19) -> -1750
B20: (M)Market research | C20: GetTattle Inc | H20: -7750 | I20: -7900 | J20: -7850 | K20: -7900 | L20: -7900 | M20: -8000 | N20: -8000 | O20: -7850 | P20: -7800 | Q20: -7750 | R20: -7750 | S20: -7750 | T20: =SUM(H20:S20) -> -94200
B21: (M)Menu | C21: COLORMARK, L.C. | H21: 0 | I21: -433.79 | J21: -432.11 | K21: 0 | L21: 0 | M21: -54150.71 | N21: 0 | O21: 0 | P21: 0 | Q21: 0 | R21: 0 | S21: -183.24 | T21: =SUM(H21:S21) -> -55199.85
B22: (M)Menu | C22: COLORMARK, L.C. | D22: System Menu | H22: 0 | I22: 0 | J22: 0 | K22: 0 | L22: 0 | M22: 0 | N22: 0 | O22: 0 | P22: 0 | Q22: 0 | R22: 0 | S22: -31964.9 | T22: =SUM(H22:S22) -> -31964.9
B23: (M)Menu Development | C23: COLORMARK, L.C. | D23: Value Meal | H23: 0 | I23: 0 | J23: -1534.07 | K23: 0 | L23: 0 | M23: 0 | N23: 0 | O23: 0 | P23: 0 | Q23: 0 | R23: 0 | S23: 0 | T23: =SUM(H23:S23) -> -1534.07
B24: (M)Menu Development | C24: COLORMARK, L.C. | H24: 0 | I24: -309.63 | J24: 0 | K24: 0 | L24: 0 | M24: -737.64 | N24: 0 | O24: 0 | P24: 0 | Q24: 0 | R24: 0 | S24: 0 | T24: =SUM(H24:S24) -> -1047.27
B25: (M)Menu Development | C25: TK America, Inc | D25: TK Sauce Development | H25: 0 | I25: 0 | J25: 0 | K25: -5000 | L25: -5000 | M25: 0 | N25: 0 | O25: 0 | P25: 0 | Q25: 0 | R25: 0 | S25: 0 | T25: =SUM(H25:S25) -> -10000
B26: (M)Misc | C26: COLORMARK, L.C. | D26: Reprint of Dots | H26: -2000 | I26: 0 | J26: 0 | K26: 0 | L26: 0 | M26: 0 | N26: 0 | O26: 0 | P26: 0 | Q26: 0 | R26: 0 | S26: 0 | T26: =SUM(H26:S26) -> -2000
B27: (M)Misc | C27: COLORMARK, L.C. | D27: misc | H27: 0 | I27: 0 | J27: 0 | K27: 0 | L27: 0 | M27: -720.21 | N27: -1420.33 | O27: 0 | P27: 0 | Q27: 0 | R27: -12939.39 | S27: -1092.02 | T27: =SUM(H27:S27) -> -16171.95
B28: (M)Misc | C28: Misc | H28: 0 | I28: 0 | J28: 0 | K28: 0 | L28: 0 | M28: 0 | N28: 0 | O28: 0 | P28: 0 | Q28: 0 | R28: -178.98 | S28: 0 | T28: =SUM(H28:S28) -> -178.98
B29: (M)Misc | C29: Stingray Worldwide LLC | D29: Misc | H29: 0 | I29: 0 | J29: 0 | K29: 0 | L29: 0 | M29: 0 | N29: 0 | O29: 0 | P29: 0 | Q29: 0 | R29: 0 | S29: -4500.59 | T29: =SUM(H29:S29) -> -4500.59
B30: (M)Music | C30: Creative Media Solutions, LLC _Juke Boxy | H30: -1520 | I30: -1482 | J30: -1482 | K30: -1501 | L30: -1501 | M30: -1425 | N30: -1653 | O30: -1653 | P30: -1653 | Q30: -8731 | R30: -2204 | S30: -2223 | T30: =SUM(H30:S30) -> -27028
B31: (M)National Advertisement | C31: Calise Partners, LLC Imaginuity | D31: Paid Media | E31: Working | H31: -45000 | I31: -65000 | J31: -70000 | K31: -120000 | L31: -200000 | M31: -206000 | N31: 44407.77 | O31: 0 | P31: 0 | Q31: 0 | R31: 0 | S31: 0 | T31: =SUM(H31:S31) -> -661592.23
B32: (M)National Advertisement | C32: Brandverge, Inc. | D32: Paid Media | E32: Working | H32: 0 | I32: 0 | J32: 0 | K32: 0 | L32: 0 | M32: 0 | N32: -200000 | O32: -200000 | P32: -200000 | Q32: -160000 | R32: -160000 | S32: -160330 | T32: =SUM(H32:S32) -> -1080330
B33: (M)National Advertisement | C33: Marketing Informatics LLC | D33: Digital Ads Platfrom | E33: Working | H33: 0 | I33: 0 | J33: 0 | K33: 0 | L33: -1000 | M33: -500 | N33: -500 | O33: -1000 | P33: -500 | Q33: -500 | R33: -500 | S33: -500 | T33: =SUM(H33:S33) -> -5000
B34: (M)National Advertisement | C34: Calise Partners, LLC Imaginuity | D34: NRO/ Local Media | E34: Working | H34: 0 | I34: 0 | J34: 0 | K34: -28499.6 | L34: 0 | M34: -3921.57 | N34: -3921.57 | O34: -3921.57 | P34: 0 | Q34: 0 | R34: 0 | S34: 0 | T34: =SUM(H34:S34) -> -40264.31
B35: (M)National Advertisement | C35: Brandverge, Inc. | D35: NRO/ Local Media | E35: Working | H35: 0 | I35: 0 | J35: 0 | K35: 0 | L35: 0 | M35: 0 | N35: 0 | O35: 0 | P35: 0 | Q35: 0 | R35: 0 | S35: -3299 | T35: =SUM(H35:S35) -> -3299
B36: (M)National Advertisement | C36: CossmanPR LLC | D36: NRO/ Local Media | E36: Working | H36: 0 | I36: 0 | J36: 0 | K36: 0 | L36: -1948.33 | M36: 0 | N36: 0 | O36: 0 | P36: 0 | Q36: 0 | R36: 0 | S36: 0 | T36: =SUM(H36:S36) -> -1948.33
B37: (M)Nutrition Fact | C37: Nutritional Information Services | D37: New Recipes, Par Frying, etc | H37: 0 | I37: -150 | J37: 0 | K37: 0 | L37: 0 | M37: 0 | N37: -40 | O37: 0 | P37: 0 | Q37: 0 | R37: 0 | S37: 0 | T37: =SUM(H37:S37) -> -190
B38: (M)Others | C38: Freshworks Inc Dept # 880636 | D38: Software | H38: 0 | I38: 0 | J38: 0 | K38: 0 | L38: -2187.44 | M38: 0 | N38: 0 | O38: 0 | P38: 0 | Q38: 0 | R38: 0 | S38: 0 | T38: =SUM(H38:S38) -> -2187.44
B39: (M)Others | C39: Mirus Information Tech Service, Inc | D39: Data Management | H39: -11378.43 | I39: -11304.43 | J39: -11476 | K39: -11828 | L39: -11628 | M39: -11780 | N39: -12232 | O39: -11780 | P39: -11552 | Q39: -11728 | R39: -11752 | S39: -11552 | T39: =SUM(H39:S39) -> -139990.86
B40: (M)Others | C40: Bonchon Holdings LLC | D40: Travel & Expenses | H40: -343.52 | I40: -1341.33 | J40: -3120.36 | K40: -841.44 | L40: -317.36 | M40: -1448.49 | N40: -1376.74 | O40: -7886.16 | P40: -821.18 | Q40: -3085.49 | R40: -968.69 | S40: -1411.51 | T40: =SUM(H40:S40) -> -22962.27
B41: (M)Others | C41: COLORMARK, L.C. | D41: Misc | H41: 0 | I41: 0 | J41: -3304.74 | K41: 0 | L41: 0 | M41: 0 | N41: 0 | O41: 0 | P41: 0 | Q41: 0 | R41: 0 | S41: 0 | T41: =SUM(H41:S41) -> -3304.74
B42: (M)Others | C42: Ada settlement | H42: 0 | I42: 0 | J42: 0 | K42: 0 | L42: 0 | M42: -6500 | N42: 0 | O42: 0 | P42: -16500 | Q42: 0 | R42: 0 | S42: 0 | T42: =SUM(H42:S42) -> -23000
...

Sheet Marketing Fund 2026 Plan
E1: -1
B2: G/L Account | C2: Vendor in SAP | D2: Description | E2: Memo | F2: 3PD | H2: Plan
H3: F26P01 | I3: F26P02 | J3: F26P03 | K3: F26P04 | L3: F26P05 | M3: F26P06 | N3: F26P07 | O3: F26P08 | P3: F26P09 | Q3: F26P10 | R3: F26P11 | S3: F26P12 | T3: FY
B4: 4112211 Marketing Fee Incomes | H4: 278297.64 | I4: 254978.11 | J4: 277449.73 | K4: 271510.46 | L4: 290630.55 | M4: 278280.59 | N4: 541292.27 | O4: 573539.1 | P4: 539469.96 | Q4: 588719.06 | R4: 567395.9 | S4: 630609.47 | T4: =SUM(H4:S4) -> 5092172.9
B5: 4112212 Marketing fee incomes- Pepsi | H5: 0 | I5: 0 | J5: 0 | K5: 0 | L5: 0 | M5: 0 | N5: 0 | O5: 0 | P5: 0 | Q5: 0 | R5: 0 | S5: 0 | T5: =SUM(H5:S5) -> 0
B6: 4112213 Marketing fee incomes- Others | H6: 0 | I6: 0 | J6: 0 | K6: 0 | L6: 0 | M6: 0 | N6: 0 | O6: 0 | P6: 0 | Q6: 0 | R6: 0 | S6: 0 | T6: =SUM(H6:S6) -> 0
B7: Total Marketing income | H7: =SUM(H4:H6) -> 278297.64 | I7: =SUM(I4:I6) -> 254978.11 | J7: =SUM(J4:J6) -> 277449.73 | K7: =SUM(K4:K6) -> 271510.46 | L7: =SUM(L4:L6) -> 290630.55 | M7: =SUM(M4:M6) -> 278280.59 | N7: =SUM(N4:N6) -> 541292.27 | O7: =SUM(O4:O6) -> 573539.1 | ... U7: =SUM(U4:U6) -> 0
T8: =SUM(H8:H8) -> 0
B9: (M)Agency | C9: CarsonDoyle Creative Agency, Ltd. | D9: Retainer | H9: -26000 | I9: -26000 | J9: -26000 | K9: -26000 | L9: -26000 | M9: -26000 | N9: -26000 | O9: -26000 | P9: -26000 | Q9: -26000 | R9: -26000 | S9: -26000 | T9: =SUM(H9:S9) -> -312000
B10: (M)Agency | C10: CossmanPR LLC | D10: Retainer | H10: -6500 | I10: -6500 | J10: -6500 | K10: -6500 | L10: -6500 | M10: -6500 | N10: -6500 | O10: -6500 | P10: -6500 | Q10: -6500 | R10: -6500 | S10: -6500 | T10: =SUM(H10:S10) -> -78000
B11: (M)Agency | C11: Veylan Inc | D11: Retainer/AI Media/Marketing Tool | H11: -10000 | I11: -10000 | J11: -10000 | K11: -10000 | L11: -10000 | M11: -10000 | N11: -10000 | O11: -10000 | P11: -10000 | Q11: -10000 | R11: -10000 | S11: -10000 | T11: =SUM(H11:S11) -> -120000
B12: (M)CRM/Loyalty | C12: Fishbowl Inc. | D12: Crunch Club Email Sends | H12: -6700 | I12: -6700 | J12: -6700 | K12: -6700 | L12: -6700 | M12: -6700 | N12: -6700 | O12: -6700 | P12: -6700 | Q12: -6700 | R12: -6700 | S12: -6700 | T12: =SUM(H12:S12) -> -80400
B13: (M)Market Research | C13: GetTattle Inc | D13: Guest Recovery | H13: -1500 | I13: 0 | J13: 0 | K13: -1500 | L13: 0 | M13: 0 | N13: -1500 | O13: 0 | P13: 0 | Q13: -1500 | R13: 0 | S13: 0 | T13: =SUM(H13:S13) -> -6000
B14: (M)Market Research | C14: GetTattle Inc | D14: Guest Survey Platform | H14: -7900 | I14: -8000 | J14: -8100 | K14: -8200 | L14: -8300 | M14: -8400 | N14: -8500 | O14: -8600 | P14: -8700 | Q14: -8800 | R14: -8900 | S14: -9000 | T14: =SUM(H14:S14) -> -101400
B15: (M)Market Research | C15: Survey Monkey | D15: Platform Subscription | H15: 0 | I15: 0 | J15: 0 | K15: 0 | L15: 0 | M15: 0 | N15: 0 | O15: 0 | P15: -550 | Q15: 0 | R15: 0 | S15: 0 | T15: =SUM(H15:S15) -> -550
B16: (M)Menu Development | D16: AI menu pricing Tool | H16: 0 | I16: 0 | J16: 0 | K16: 0 | L16: -15000 | M16: -15000 | N16: -15000 | O16: 0 | P16: 0 | Q16: 0 | R16: 0 | S16: 0 | T16: =SUM(H16:S16) -> -45000
B17: (M)Menu Development | C17: COLORMARK, L.C. | D17: System Menu | H17: 0 | I17: 0 | J17: -70000 | K17: 0 | L17: 0 | M17: 0 | N17: -70000 | O17: 0 | P17: 0 | Q17: 0 | R17: 0 | S17: -70000 | T17: =SUM(H17:S17) -> -210000
B18: (M)Menu Development | C18: COLORMARK, L.C. | D18: Monthly Promotions | H18: -1000 | I18: -1000 | J18: -1000 | K18: -1000 | L18: -1000 | M18: -1000 | N18: -1000 | O18: -1000 | P18: -1000 | Q18: -1000 | R18: -1000 | S18: -1000 | T18: =SUM(H18:S18) -> -12000
B19: (M)Misc | C19: COLORMARK, L.C. | D19: Misc Print Production | H19: -500 | I19: -500 | J19: -500 | K19: -500 | L19: -500 | M19: -500 | N19: -500 | O19: -500 | P19: -500 | Q19: -500 | R19: -500 | S19: -500 | T19: =SUM(H19:S19) -> -6000
B20: (M)Misc | C20: Stingray Worldwide LLC | D20: Uniforms | H20: 0 | I20: 0 | J20: -3000 | K20: 0 | L20: 0 | M20: -3000 | N20: 0 | O20: 0 | P20: -3000 | Q20: 0 | R20: 0 | S20: 0 | T20: =SUM(H20:S20) -> -9000
B21: (M)Misc | D21: Misc | H21: -3500 | I21: -3500 | J21: -3500 | K21: -3500 | L21: -3500 | M21: -3500 | N21: -3500 | O21: -3500 | P21: -3500 | Q21: -3500 | R21: -3500 | S21: -3500 | T21: =SUM(H21:S21) -> -42000
B22: (M)Music | C22: Creative Media Solutions, LLC _Juke Boxy | D22: Playlist Subscription | H22: -2320 | I22: -2360 | J22: -2400 | K22: -2440 | L22: -2480 | M22: -2520 | N22: -2560 | O22: -2600 | P22: -2640 | Q22: -2680 | R22: -2720 | S22: -2760 | T22: =SUM(H22:S22) -> -30480
B23: (M)National Advertisement | C23: Marketing Informatics LLC | D23: Local Media | E23: Working | H23: -1000 | I23: -1000 | J23: -1000 | K23: -1000 | L23: -1000 | M23: -1000 | N23: -1000 | O23: -1000 | P23: -1000 | Q23: -1000 | R23: -1000 | S23: -1000 | T23: =SUM(H23:S23) -> -12000
B24: (M)National Advertisement | C24: CossmanPR LLC | D24: Local Media | E24: Working | H24: -5000 | I24: -5000 | J24: -5000 | K24: -5000 | L24: -5000 | M24: -5000 | N24: -5000 | O24: -5000 | P24: -5000 | Q24: -5000 | R24: -5000 | S24: -5000 | T24: =SUM(H24:S24) -> -60000
B25: (M)National Advertisement | C25: Brandverge, Inc. | D25: NRO Media | E25: Working | H25: -5000 | I25: -5000 | J25: -5000 | K25: -5000 | L25: -5000 | M25: -5000 | N25: -5000 | O25: -5000 | P25: -5000 | Q25: -5000 | R25: -5000 | S25: -5000 | T25: =SUM(H25:S25) -> -60000
B26: (M)National Advertisement | C26: Veylan Inc | D26: National Digital Paid Media | E26: Working | H26: -150000 | I26: -150000 | J26: -150000 | K26: -150000 | L26: -150000 | M26: -150000 | N26: -150000 | O26: -150000 | P26: -150000 | Q26: -150000 | R26: -150000 | S26: -150000 | T26: =SUM(H26:S26) -> -1800000
B27: (M)Nutrition Fact | C27: Nutritional Information Services | D27: New/Revised Recipes | H27: 0 | I27: 0 | J27: -300 | K27: 0 | L27: 0 | M27: -300 | N27: 0 | O27: 0 | P27: -300 | Q27: 0 | R27: 0 | S27: -300 | T27: =SUM(H27:S27) -> -1200
B28: (M)Overhead expense | C28: Overhead | D28: Overhead | H28: -50000 | I28: -55000 | J28: -55000 | K28: -55000 | L28: -55000 | M28: -55000 | N28: -55000 | O28: -55000 | P28: -55000 | Q28: -55000 | R28: -55000 | S28: -55000 | T28: =SUM(H28:S28) -> -655000
B29: (M)Photo & Video | C29: CarsonDoyle Creative Agency,Ltd. | D29: Content Production | H29: 0 | I29: 0 | J29: 0 | K29: 0 | L29: 0 | M29: 0 | N29: -100000 | O29: 0 | P29: 0 | Q29: 0 | R29: 0 | S29: 0 | T29: =SUM(H29:S29) -> -100000
B30: (M)Photo & Video | C30: Korean Freelancers | D30: Freelance Designer | H30: 0 | I30: 0 | J30: -700 | K30: 0 | L30: 0 | M30: -700 | N30: 0 | O30: 0 | P30: -700 | Q30: 0 | R30: 0 | S30: -700 | T30: =SUM(H30:S30) -> -2800
B31: (M)Photo & Video | C31: Robert Tsai Photography | D31: Menu/Lifestyle Photography | H31: 0 | I31: -4300 | J31: 0 | K31: -4300 | L31: 0 | M31: -4300 | N31: 0 | O31: -4300 | P31: 0 | Q31: -4300 | R31: 0 | S31: -4300 | T31: =SUM(H31:S31) -> -25800
B32: (M)Promotions | C32: Doordash, Inc | D32: 3PD Media | E32: Working | F32: 3rd Party Delivery | H32: -58000 | I32: -55000 | J32: -58000 | K32: -50000 | L32: -50000 | M32: -50000 | N32: -50000 | O32: -50000 | P32: -50000 | Q32: -50000 | R32: -58000 | S32: -58000 | T32: =SUM(H32:S32) -> -637000
B33: (M)Promotions | C33: ezCarter, Inc | D33: Catering Promo | E33: Working | F33: 3rd Party Delivery | H33: 0 | I33: 0 | J33: -10000 | K33: 0 | L33: 0 | M33: -10000 | N33: 0 | O33: 0 | P33: -10000 | Q33: 0 | R33: 0 | S33: -10000 | T33: =SUM(H33:S33) -> -40000
B34: (M)Promotions | C34: Uber Portier, Llc | D34: 3PD Media | E34: Working | F34: 3rd Party Delivery | H34: -68000 | I34: -65000 | J34: -68000 | K34: -60000 | L34: -60000 | M34: -60000 | N34: -60000 | O34: -60000 | P34: -60000 | Q34: -60000 | R34: -68000 | S34: -68000 | T34: =SUM(H34:S34) -> -757000
B35: (M)Promotions | C35: Doordash, Inc | D35: Promotional Activation | E35: Working | F35: 3rd Party Delivery | H35: 0 | I35: -10000 | J35: 0 | K35: -10000 | L35: 0 | M35: -10000 | N35: 0 | O35: -10000 | P35: 0 | Q35: -10000 | R35: 0 | S35: -10000 | T35: =SUM(H35:S35) -> -60000
B36: (M)Promotions | C36: CossmanPR LLC | D36: Influencers - Brand Ambassedors | E36: Working | H36: -30000 | I36: -30000 | J36: -30000 | K36: -30000 | L36: -30000 | M36: -30000 | N36: -30000 | O36: -30000 | P36: -30000 | Q36: -30000 | R36: -30000 | S36: -30000 | T36: =SUM(H36:S36) -> -360000
B37: (M)Promotions | C37: COLORMARK, L.C. | D37: National Rollout POP Production | H37: -20000 | I37: 0 | J37: -20000 | K37: 0 | L37: -20000 | M37: 0 | N37: -20000 | O37: 0 | P37: -20000 | Q37: 0 | R37: -20000 | S37: 0 | T37: =SUM(H37:S37) -> -120000
B38: (M)Promotions | C38: CossmanPR LLC | D38: National Rollout PR Activation | E38: Working | H38: -5000 | I38: -5000 | J38: -5000 | K38: -5000 | L38: -5000 | M38: -5000 | N38: -5000 | O38: -5000 | P38: -5000 | Q38: -5000 | R38: -5000 | S38: -5000 | T38: =SUM(H38:S38) -> -60000
B39: (M)Promotions | C39: Stingray Worldwide LLC | D39: Merchandising | H39: -5000 | I39: 0 | J39: 0 | K39: -5000 | L39: 0 | M39: 0 | N39: -5000 | O39: 0 | P39: -5000 | Q39: 0 | R39: -5000 | S39: 0 | T39: =SUM(H39:S39) -> -25000
B40: (M)Social Media | C40: Sprout Social, Inc | D40: Social Scheduling and Analytics | H40: -1200 | I40: -1200 | J40: -1200 | K40: -1200 | L40: -1200 | M40: -1200 | N40: -1200 | O40: -1200 | P40: -1200 | Q40: -1200 | R40: -1200 | S40: -1200 | T40: =SUM(H40:S40) -> -14400
...
